{"modules": [{"testcases": [{"result": "success", "name": "test_a_better_way_of_asserting_equality"}, {"result": "success", "name": "test_assert_equality"}, {"result": "success", "name": "test_assert_truth"}, {"result": "success", "name": "test_assert_with_message"}, {"result": "success", "name": "test_fill_in_values"}, {"result": "success", "name": "test_that_sometimes_we_need_to_know_the_class_type"}, {"result": "success", "name": "test_that_unittest_asserts_work_the_same_way_as_python_asserts"}], "nr_error": 0, "nr_success": 7, "name": "test.test_asserts.AboutAsserts", "nr_failed": 0}, {"testcases": [{"error": {"message": "AttributeError: 'AboutAttributeAccess' object has no attribute 'assertMatch'", "traceback": [{"linenr": 329, "function": "run", "line": "testMethod()", "filename": "/usr/local/Cellar/python/2.7.12/Frameworks/Python.framework/Versions/2.7/lib/python2.7/unittest/case.py"}, {"linenr": 48, "function": "test_all_attribute_reads_are_caught", "line": "self.assertMatch(__, catcher.foobar)", "filename": "/Users/ops/Projects/PyKata/test/test_attribute_access.py"}]}, "result": "error", "name": "test_all_attribute_reads_are_caught"}, {"error": {"message": "AttributeError: 'AboutAttributeAccess' object has no attribute 'assertMatch'", "traceback": [{"linenr": 329, "function": "run", "line": "testMethod()", "filename": "/usr/local/Cellar/python/2.7.12/Frameworks/Python.framework/Versions/2.7/lib/python2.7/unittest/case.py"}, {"linenr": 31, "function": "test_calling_getattribute_causes_an_attribute_error", "line": "self.assertMatch(__, exception[0])", "filename": "/Users/ops/Projects/PyKata/test/test_attribute_access.py"}]}, "result": "error", "name": "test_calling_getattribute_causes_an_attribute_error"}, {"error": {"message": "NameError: global name '__' is not defined", "traceback": [{"linenr": 329, "function": "run", "line": "testMethod()", "filename": "/usr/local/Cellar/python/2.7.12/Frameworks/Python.framework/Versions/2.7/lib/python2.7/unittest/case.py"}, {"linenr": 22, "function": "test_calling_undefined_functions_normally_results_in_errors", "line": "self.assertEqual(__, exception.__class__.__name__)", "filename": "/Users/ops/Projects/PyKata/test/test_attribute_access.py"}]}, "result": "error", "name": "test_calling_undefined_functions_normally_results_in_errors"}, {"error": {"message": "AttributeError: 'AboutAttributeAccess' object has no attribute 'assertMatch'", "traceback": [{"linenr": 329, "function": "run", "line": "testMethod()", "filename": "/usr/local/Cellar/python/2.7.12/Frameworks/Python.framework/Versions/2.7/lib/python2.7/unittest/case.py"}, {"linenr": 69, "function": "test_changing_getattribute_will_affect__the_getattr_function", "line": "self.assertMatch(__, getattr(catcher, 'any_attribute'))", "filename": "/Users/ops/Projects/PyKata/test/test_attribute_access.py"}]}, "result": "error", "name": "test_changing_getattribute_will_affect__the_getattr_function"}, {"error": {"message": "NameError: global name '__' is not defined", "traceback": [{"linenr": 329, "function": "run", "line": "testMethod()", "filename": "/usr/local/Cellar/python/2.7.12/Frameworks/Python.framework/Versions/2.7/lib/python2.7/unittest/case.py"}, {"linenr": 85, "function": "test_foo_attributes_are_caught", "line": "self.assertEqual(__, catcher.foo_bar)", "filename": "/Users/ops/Projects/PyKata/test/test_attribute_access.py"}]}, "result": "error", "name": "test_foo_attributes_are_caught"}, {"error": {"message": "NameError: global name '__' is not defined", "traceback": [{"linenr": 329, "function": "run", "line": "testMethod()", "filename": "/usr/local/Cellar/python/2.7.12/Frameworks/Python.framework/Versions/2.7/lib/python2.7/unittest/case.py"}, {"linenr": 155, "function": "test_getattr_ignores_known_attributes", "line": "self.assertEqual(__, catcher.no_of_getattr_calls)", "filename": "/Users/ops/Projects/PyKata/test/test_attribute_access.py"}]}, "result": "error", "name": "test_getattr_ignores_known_attributes"}, {"error": {"message": "NameError: global name '__' is not defined", "traceback": [{"linenr": 329, "function": "run", "line": "testMethod()", "filename": "/usr/local/Cellar/python/2.7.12/Frameworks/Python.framework/Versions/2.7/lib/python2.7/unittest/case.py"}, {"linenr": 162, "function": "test_getattr_only_catches_unknown_attributes", "line": "self.assertEqual(__,", "filename": "/Users/ops/Projects/PyKata/test/test_attribute_access.py"}]}, "result": "error", "name": "test_getattr_only_catches_unknown_attributes"}, {"error": {"message": "NameError: global name '__' is not defined", "traceback": [{"linenr": 329, "function": "run", "line": "testMethod()", "filename": "/usr/local/Cellar/python/2.7.12/Frameworks/Python.framework/Versions/2.7/lib/python2.7/unittest/case.py"}, {"linenr": 133, "function": "test_getattribute_is_a_bit_overzealous_sometimes", "line": "self.assertEqual(__, stack_depth)", "filename": "/Users/ops/Projects/PyKata/test/test_attribute_access.py"}]}, "result": "error", "name": "test_getattribute_is_a_bit_overzealous_sometimes"}, {"error": {"message": "NameError: global name '__' is not defined", "traceback": [{"linenr": 329, "function": "run", "line": "testMethod()", "filename": "/usr/local/Cellar/python/2.7.12/Frameworks/Python.framework/Versions/2.7/lib/python2.7/unittest/case.py"}, {"linenr": 229, "function": "test_in_this_case_private_attributes_remain_unmangled", "line": "self.assertEqual(__, setter._num_of_private_coconuts)", "filename": "/Users/ops/Projects/PyKata/test/test_attribute_access.py"}]}, "result": "error", "name": "test_in_this_case_private_attributes_remain_unmangled"}, {"error": {"message": "AttributeError: 'AboutAttributeAccess' object has no attribute 'assertMatch'", "traceback": [{"linenr": 329, "function": "run", "line": "testMethod()", "filename": "/usr/local/Cellar/python/2.7.12/Frameworks/Python.framework/Versions/2.7/lib/python2.7/unittest/case.py"}, {"linenr": 53, "function": "test_intercepting_return_values_can_disrupt_the_call_chain", "line": "self.assertMatch(__, catcher.foobaz)  # This is fine", "filename": "/Users/ops/Projects/PyKata/test/test_attribute_access.py"}]}, "result": "error", "name": "test_intercepting_return_values_can_disrupt_the_call_chain"}, {"error": {"message": "NameError: global name '__' is not defined", "traceback": [{"linenr": 329, "function": "run", "line": "testMethod()", "filename": "/usr/local/Cellar/python/2.7.12/Frameworks/Python.framework/Versions/2.7/lib/python2.7/unittest/case.py"}, {"linenr": 224, "function": "test_it_mangles_some_internal_attributes", "line": "self.assertEqual(__, setter.altered_num_of_coconuts)", "filename": "/Users/ops/Projects/PyKata/test/test_attribute_access.py"}]}, "result": "error", "name": "test_it_mangles_some_internal_attributes"}, {"error": {"message": "NameError: global name '__' is not defined", "traceback": [{"linenr": 329, "function": "run", "line": "testMethod()", "filename": "/usr/local/Cellar/python/2.7.12/Frameworks/Python.framework/Versions/2.7/lib/python2.7/unittest/case.py"}, {"linenr": 216, "function": "test_it_modifies_external_attribute_as_expected", "line": "self.assertEqual(__, setter.altered_e)", "filename": "/Users/ops/Projects/PyKata/test/test_attribute_access.py"}]}, "result": "error", "name": "test_it_modifies_external_attribute_as_expected"}, {"error": {"message": "AttributeError: 'AboutAttributeAccess' object has no attribute 'assertMatch'", "traceback": [{"linenr": 329, "function": "run", "line": "testMethod()", "filename": "/usr/local/Cellar/python/2.7.12/Frameworks/Python.framework/Versions/2.7/lib/python2.7/unittest/case.py"}, {"linenr": 94, "function": "test_non_foo_messages_are_treated_normally", "line": "self.assertMatch(__, ex[0])", "filename": "/Users/ops/Projects/PyKata/test/test_attribute_access.py"}]}, "result": "error", "name": "test_non_foo_messages_are_treated_normally"}, {"error": {"message": "NameError: global name '__' is not defined", "traceback": [{"linenr": 329, "function": "run", "line": "testMethod()", "filename": "/usr/local/Cellar/python/2.7.12/Frameworks/Python.framework/Versions/2.7/lib/python2.7/unittest/case.py"}, {"linenr": 186, "function": "test_setattr_intercepts_attribute_assignments", "line": "self.assertEqual(__, fanboy.a_pie)", "filename": "/Users/ops/Projects/PyKata/test/test_attribute_access.py"}]}, "result": "error", "name": "test_setattr_intercepts_attribute_assignments"}], "nr_error": 14, "nr_success": 0, "name": "test.test_attribute_access.AboutAttributeAccess", "nr_failed": 0}, {"testcases": [{"error": {"message": "NameError: global name '__' is not defined", "traceback": [{"linenr": 329, "function": "run", "line": "testMethod()", "filename": "/usr/local/Cellar/python/2.7.12/Frameworks/Python.framework/Versions/2.7/lib/python2.7/unittest/case.py"}, {"linenr": 134, "function": "test_classes_and_instances_do_not_share_instance_attributes", "line": "self.assertEqual(__, fido.get_name_from_instance())", "filename": "/Users/ops/Projects/PyKata/test/test_class_attributes.py"}]}, "result": "error", "name": "test_classes_and_instances_do_not_share_instance_attributes"}, {"error": {"message": "NameError: global name '__' is not defined", "traceback": [{"linenr": 329, "function": "run", "line": "testMethod()", "filename": "/usr/local/Cellar/python/2.7.12/Frameworks/Python.framework/Versions/2.7/lib/python2.7/unittest/case.py"}, {"linenr": 140, "function": "test_classes_and_instances_do_share_class_attributes", "line": "self.assertEqual(__, fido.get_name())", "filename": "/Users/ops/Projects/PyKata/test/test_class_attributes.py"}]}, "result": "error", "name": "test_classes_and_instances_do_share_class_attributes"}, {"error": {"message": "NameError: global name '__' is not defined", "traceback": [{"linenr": 329, "function": "run", "line": "testMethod()", "filename": "/usr/local/Cellar/python/2.7.12/Frameworks/Python.framework/Versions/2.7/lib/python2.7/unittest/case.py"}, {"linenr": 26, "function": "test_classes_are_objects_too", "line": "self.assertEqual(__, issubclass(self.Dog, object))", "filename": "/Users/ops/Projects/PyKata/test/test_class_attributes.py"}]}, "result": "error", "name": "test_classes_are_objects_too"}, {"error": {"message": "NameError: global name '__' is not defined", "traceback": [{"linenr": 329, "function": "run", "line": "testMethod()", "filename": "/usr/local/Cellar/python/2.7.12/Frameworks/Python.framework/Versions/2.7/lib/python2.7/unittest/case.py"}, {"linenr": 23, "function": "test_classes_are_types", "line": "self.assertEqual(__, self.Dog.__class__ == type)", "filename": "/Users/ops/Projects/PyKata/test/test_class_attributes.py"}]}, "result": "error", "name": "test_classes_are_types"}, {"error": {"message": "NameError: global name '__' is not defined", "traceback": [{"linenr": 329, "function": "run", "line": "testMethod()", "filename": "/usr/local/Cellar/python/2.7.12/Frameworks/Python.framework/Versions/2.7/lib/python2.7/unittest/case.py"}, {"linenr": 33, "function": "test_classes_have_methods", "line": "self.assertEqual(__, len(dir(self.Dog)))", "filename": "/Users/ops/Projects/PyKata/test/test_class_attributes.py"}]}, "result": "error", "name": "test_classes_have_methods"}, {"error": {"message": "AttributeError: 'AboutClassAttributes' object has no attribute 'assertMatch'", "traceback": [{"linenr": 329, "function": "run", "line": "testMethod()", "filename": "/usr/local/Cellar/python/2.7.12/Frameworks/Python.framework/Versions/2.7/lib/python2.7/unittest/case.py"}, {"linenr": 89, "function": "test_classmethods_are_not_independent_of_instance_methods", "line": "self.assertMatch(__, fido.growl())", "filename": "/Users/ops/Projects/PyKata/test/test_class_attributes.py"}]}, "result": "error", "name": "test_classmethods_are_not_independent_of_instance_methods"}, {"error": {"message": "AttributeError: 'AboutClassAttributes' object has no attribute 'assertMatch'", "traceback": [{"linenr": 329, "function": "run", "line": "testMethod()", "filename": "/usr/local/Cellar/python/2.7.12/Frameworks/Python.framework/Versions/2.7/lib/python2.7/unittest/case.py"}, {"linenr": 128, "function": "test_classmethods_can_not_be_used_as_properties", "line": "self.assertMatch(__, ex[0])", "filename": "/Users/ops/Projects/PyKata/test/test_class_attributes.py"}]}, "result": "error", "name": "test_classmethods_can_not_be_used_as_properties"}, {"error": {"message": "NameError: global name '__' is not defined", "traceback": [{"linenr": 329, "function": "run", "line": "testMethod()", "filename": "/usr/local/Cellar/python/2.7.12/Frameworks/Python.framework/Versions/2.7/lib/python2.7/unittest/case.py"}, {"linenr": 37, "function": "test_creating_objects_without_defining_a_class", "line": "self.assertEqual(__, len(dir(singularity)))", "filename": "/Users/ops/Projects/PyKata/test/test_class_attributes.py"}]}, "result": "error", "name": "test_creating_objects_without_defining_a_class"}, {"error": {"message": "NameError: global name '__' is not defined", "traceback": [{"linenr": 329, "function": "run", "line": "testMethod()", "filename": "/usr/local/Cellar/python/2.7.12/Frameworks/Python.framework/Versions/2.7/lib/python2.7/unittest/case.py"}, {"linenr": 43, "function": "test_defining_attributes_on_individual_objects", "line": "self.assertEqual(__, fido.legs)", "filename": "/Users/ops/Projects/PyKata/test/test_class_attributes.py"}]}, "result": "error", "name": "test_defining_attributes_on_individual_objects"}, {"error": {"message": "NameError: global name '__' is not defined", "traceback": [{"linenr": 329, "function": "run", "line": "testMethod()", "filename": "/usr/local/Cellar/python/2.7.12/Frameworks/Python.framework/Versions/2.7/lib/python2.7/unittest/case.py"}, {"linenr": 49, "function": "test_defining_functions_on_individual_objects", "line": "self.assertEqual(__, fido.wag())", "filename": "/Users/ops/Projects/PyKata/test/test_class_attributes.py"}]}, "result": "error", "name": "test_defining_functions_on_individual_objects"}, {"error": {"message": "AttributeError: 'AboutClassAttributes' object has no attribute 'assertMatch'", "traceback": [{"linenr": 329, "function": "run", "line": "testMethod()", "filename": "/usr/local/Cellar/python/2.7.12/Frameworks/Python.framework/Versions/2.7/lib/python2.7/unittest/case.py"}, {"linenr": 85, "function": "test_like_all_objects_classes_can_have_singleton_methods", "line": "self.assertMatch(__, self.Dog2.growl())", "filename": "/Users/ops/Projects/PyKata/test/test_class_attributes.py"}]}, "result": "error", "name": "test_like_all_objects_classes_can_have_singleton_methods"}, {"error": {"message": "NameError: global name '__' is not defined", "traceback": [{"linenr": 329, "function": "run", "line": "testMethod()", "filename": "/usr/local/Cellar/python/2.7.12/Frameworks/Python.framework/Versions/2.7/lib/python2.7/unittest/case.py"}, {"linenr": 20, "function": "test_new_style_class_objects_are_objects", "line": "self.assertEqual(__, isinstance(fido, object))", "filename": "/Users/ops/Projects/PyKata/test/test_class_attributes.py"}]}, "result": "error", "name": "test_new_style_class_objects_are_objects"}, {"error": {"message": "NameError: global name '__' is not defined", "traceback": [{"linenr": 329, "function": "run", "line": "testMethod()", "filename": "/usr/local/Cellar/python/2.7.12/Frameworks/Python.framework/Versions/2.7/lib/python2.7/unittest/case.py"}, {"linenr": 30, "function": "test_objects_have_methods", "line": "self.assertEqual(__, len(dir(fido)))", "filename": "/Users/ops/Projects/PyKata/test/test_class_attributes.py"}]}, "result": "error", "name": "test_objects_have_methods"}, {"error": {"message": "AttributeError: 'AboutClassAttributes' object has no attribute 'assertMatch'", "traceback": [{"linenr": 329, "function": "run", "line": "testMethod()", "filename": "/usr/local/Cellar/python/2.7.12/Frameworks/Python.framework/Versions/2.7/lib/python2.7/unittest/case.py"}, {"linenr": 62, "function": "test_other_objects_are_not_affected_by_these_singleton_functions", "line": "self.assertMatch(__, ex[0])", "filename": "/Users/ops/Projects/PyKata/test/test_class_attributes.py"}]}, "result": "error", "name": "test_other_objects_are_not_affected_by_these_singleton_functions"}, {"error": {"message": "AttributeError: 'AboutClassAttributes' object has no attribute 'assertMatch'", "traceback": [{"linenr": 329, "function": "run", "line": "testMethod()", "filename": "/usr/local/Cellar/python/2.7.12/Frameworks/Python.framework/Versions/2.7/lib/python2.7/unittest/case.py"}, {"linenr": 97, "function": "test_staticmethods_also_overshadow_instance_methods", "line": "self.assertMatch(__, fido.bark())", "filename": "/Users/ops/Projects/PyKata/test/test_class_attributes.py"}]}, "result": "error", "name": "test_staticmethods_also_overshadow_instance_methods"}, {"error": {"message": "AttributeError: 'AboutClassAttributes' object has no attribute 'assertMatch'", "traceback": [{"linenr": 329, "function": "run", "line": "testMethod()", "filename": "/usr/local/Cellar/python/2.7.12/Frameworks/Python.framework/Versions/2.7/lib/python2.7/unittest/case.py"}, {"linenr": 93, "function": "test_staticmethods_are_unbound_functions_housed_in_a_class", "line": "self.assertMatch(__, self.Dog2.bark())", "filename": "/Users/ops/Projects/PyKata/test/test_class_attributes.py"}]}, "result": "error", "name": "test_staticmethods_are_unbound_functions_housed_in_a_class"}, {"error": {"message": "NameError: global name '__' is not defined", "traceback": [{"linenr": 329, "function": "run", "line": "testMethod()", "filename": "/usr/local/Cellar/python/2.7.12/Frameworks/Python.framework/Versions/2.7/lib/python2.7/unittest/case.py"}, {"linenr": 156, "function": "test_you_can_define_class_methods_without_using_a_decorator", "line": "self.assertEqual(__, self.Dog4.a_class_method())", "filename": "/Users/ops/Projects/PyKata/test/test_class_attributes.py"}]}, "result": "error", "name": "test_you_can_define_class_methods_without_using_a_decorator"}, {"error": {"message": "NameError: global name '__' is not defined", "traceback": [{"linenr": 329, "function": "run", "line": "testMethod()", "filename": "/usr/local/Cellar/python/2.7.12/Frameworks/Python.framework/Versions/2.7/lib/python2.7/unittest/case.py"}, {"linenr": 159, "function": "test_you_can_define_static_methods_without_using_a_decorator", "line": "self.assertEqual(__, self.Dog4.a_static_method())", "filename": "/Users/ops/Projects/PyKata/test/test_class_attributes.py"}]}, "result": "error", "name": "test_you_can_define_static_methods_without_using_a_decorator"}, {"error": {"message": "NameError: global name '__' is not defined", "traceback": [{"linenr": 329, "function": "run", "line": "testMethod()", "filename": "/usr/local/Cellar/python/2.7.12/Frameworks/Python.framework/Versions/2.7/lib/python2.7/unittest/case.py"}, {"linenr": 165, "function": "test_you_can_explicitly_call_class_methods_from_instance_methods", "line": "self.assertEqual(__, fido.__class__.a_class_method())", "filename": "/Users/ops/Projects/PyKata/test/test_class_attributes.py"}]}, "result": "error", "name": "test_you_can_explicitly_call_class_methods_from_instance_methods"}], "nr_error": 19, "nr_success": 0, "name": "test.test_class_attributes.AboutClassAttributes", "nr_failed": 0}, {"testcases": [{"error": {"message": "NameError: global name '__' is not defined", "traceback": [{"linenr": 329, "function": "run", "line": "testMethod()", "filename": "/usr/local/Cellar/python/2.7.12/Frameworks/Python.framework/Versions/2.7/lib/python2.7/unittest/case.py"}, {"linenr": 156, "function": "test_all_objects_support_str_and_repr", "line": "self.assertEqual(__, str(seq))", "filename": "/Users/ops/Projects/PyKata/test/test_classes.py"}]}, "result": "error", "name": "test_all_objects_support_str_and_repr"}, {"error": {"message": "NameError: global name '___' is not defined", "traceback": [{"linenr": 329, "function": "run", "line": "testMethod()", "filename": "/usr/local/Cellar/python/2.7.12/Frameworks/Python.framework/Versions/2.7/lib/python2.7/unittest/case.py"}, {"linenr": 107, "function": "test_args_must_match_init", "line": "self.assertRaises(___, self.Dog5)  # Evaluates self.Dog5()", "filename": "/Users/ops/Projects/PyKata/test/test_classes.py"}]}, "result": "error", "name": "test_args_must_match_init"}, {"error": {"message": "AttributeError: 'AboutClasses' object has no attribute 'assertMatch'", "traceback": [{"linenr": 329, "function": "run", "line": "testMethod()", "filename": "/usr/local/Cellar/python/2.7.12/Frameworks/Python.framework/Versions/2.7/lib/python2.7/unittest/case.py"}, {"linenr": 16, "function": "test_classes_have_docstrings", "line": "self.assertMatch(__, self.Dog.__doc__)", "filename": "/Users/ops/Projects/PyKata/test/test_classes.py"}]}, "result": "error", "name": "test_classes_have_docstrings"}, {"error": {"message": "NameError: global name '__' is not defined", "traceback": [{"linenr": 329, "function": "run", "line": "testMethod()", "filename": "/usr/local/Cellar/python/2.7.12/Frameworks/Python.framework/Versions/2.7/lib/python2.7/unittest/case.py"}, {"linenr": 90, "function": "test_creating_properties_with_decorators_is_slightly_easier", "line": "self.assertEqual(__, fido.name)", "filename": "/Users/ops/Projects/PyKata/test/test_classes.py"}]}, "result": "error", "name": "test_creating_properties_with_decorators_is_slightly_easier"}, {"error": {"message": "NameError: global name '____' is not defined", "traceback": [{"linenr": 329, "function": "run", "line": "testMethod()", "filename": "/usr/local/Cellar/python/2.7.12/Frameworks/Python.framework/Versions/2.7/lib/python2.7/unittest/case.py"}, {"linenr": 116, "function": "test_different_objects_have_different_instance_variables", "line": "self.assertEqual(____, rover.name == fido.name)", "filename": "/Users/ops/Projects/PyKata/test/test_classes.py"}]}, "result": "error", "name": "test_different_objects_have_different_instance_variables"}, {"error": {"message": "NameError: global name '__' is not defined", "traceback": [{"linenr": 329, "function": "run", "line": "testMethod()", "filename": "/usr/local/Cellar/python/2.7.12/Frameworks/Python.framework/Versions/2.7/lib/python2.7/unittest/case.py"}, {"linenr": 29, "function": "test_init_method_is_the_constructor", "line": "self.assertEqual(__, dog._name)", "filename": "/Users/ops/Projects/PyKata/test/test_classes.py"}]}, "result": "error", "name": "test_init_method_is_the_constructor"}, {"error": {"message": "NameError: global name '__' is not defined", "traceback": [{"linenr": 329, "function": "run", "line": "testMethod()", "filename": "/usr/local/Cellar/python/2.7.12/Frameworks/Python.framework/Versions/2.7/lib/python2.7/unittest/case.py"}, {"linenr": 104, "function": "test_init_provides_initial_values_for_instance_variables", "line": "self.assertEqual(__, fido.name)", "filename": "/Users/ops/Projects/PyKata/test/test_classes.py"}]}, "result": "error", "name": "test_init_provides_initial_values_for_instance_variables"}, {"error": {"message": "NameError: global name '__' is not defined", "traceback": [{"linenr": 329, "function": "run", "line": "testMethod()", "filename": "/usr/local/Cellar/python/2.7.12/Frameworks/Python.framework/Versions/2.7/lib/python2.7/unittest/case.py"}, {"linenr": 139, "function": "test_inside_a_method_self_refers_to_the_containing_object", "line": "self.assertEqual(__, fido.get_self())  # Not a string!", "filename": "/Users/ops/Projects/PyKata/test/test_classes.py"}]}, "result": "error", "name": "test_inside_a_method_self_refers_to_the_containing_object"}, {"error": {"message": "NameError: global name '__' is not defined", "traceback": [{"linenr": 329, "function": "run", "line": "testMethod()", "filename": "/usr/local/Cellar/python/2.7.12/Frameworks/Python.framework/Versions/2.7/lib/python2.7/unittest/case.py"}, {"linenr": 13, "function": "test_instances_of_classes_can_be_created_adding_parentheses", "line": "self.assertEqual(__, fido.__class__.__name__)", "filename": "/Users/ops/Projects/PyKata/test/test_classes.py"}]}, "result": "error", "name": "test_instances_of_classes_can_be_created_adding_parentheses"}, {"error": {"message": "NameError: global name '__' is not defined", "traceback": [{"linenr": 329, "function": "run", "line": "testMethod()", "filename": "/usr/local/Cellar/python/2.7.12/Frameworks/Python.framework/Versions/2.7/lib/python2.7/unittest/case.py"}, {"linenr": 34, "function": "test_private_attributes_are_not_really_private", "line": "self.assertEqual(__, dog._name)", "filename": "/Users/ops/Projects/PyKata/test/test_classes.py"}]}, "result": "error", "name": "test_private_attributes_are_not_really_private"}, {"error": {"message": "NameError: global name '__' is not defined", "traceback": [{"linenr": 329, "function": "run", "line": "testMethod()", "filename": "/usr/local/Cellar/python/2.7.12/Frameworks/Python.framework/Versions/2.7/lib/python2.7/unittest/case.py"}, {"linenr": 151, "function": "test_repr_provides_a_more_complete_string_version", "line": "self.assertEqual(__, repr(fido))", "filename": "/Users/ops/Projects/PyKata/test/test_classes.py"}]}, "result": "error", "name": "test_repr_provides_a_more_complete_string_version"}, {"error": {"message": "NameError: global name '__' is not defined", "traceback": [{"linenr": 329, "function": "run", "line": "testMethod()", "filename": "/usr/local/Cellar/python/2.7.12/Frameworks/Python.framework/Versions/2.7/lib/python2.7/unittest/case.py"}, {"linenr": 147, "function": "test_str_is_used_explicitly_in_string_interpolation", "line": "self.assertEqual(__, \"My dog is \" + str(fido))", "filename": "/Users/ops/Projects/PyKata/test/test_classes.py"}]}, "result": "error", "name": "test_str_is_used_explicitly_in_string_interpolation"}, {"error": {"message": "NameError: global name '__' is not defined", "traceback": [{"linenr": 329, "function": "run", "line": "testMethod()", "filename": "/usr/local/Cellar/python/2.7.12/Frameworks/Python.framework/Versions/2.7/lib/python2.7/unittest/case.py"}, {"linenr": 143, "function": "test_str_provides_a_string_version_of_the_object", "line": "self.assertEqual(\"Fido\", str(fido))", "filename": "/Users/ops/Projects/PyKata/test/test_classes.py"}, {"linenr": 131, "function": "__str__", "line": "return __", "filename": "/Users/ops/Projects/PyKata/test/test_classes.py"}]}, "result": "error", "name": "test_str_provides_a_string_version_of_the_object"}, {"error": {"message": "NameError: global name '__' is not defined", "traceback": [{"linenr": 329, "function": "run", "line": "testMethod()", "filename": "/usr/local/Cellar/python/2.7.12/Frameworks/Python.framework/Versions/2.7/lib/python2.7/unittest/case.py"}, {"linenr": 69, "function": "test_that_name_can_be_read_as_a_property", "line": "self.assertEqual(__, fido.get_name())  # access as method", "filename": "/Users/ops/Projects/PyKata/test/test_classes.py"}]}, "result": "error", "name": "test_that_name_can_be_read_as_a_property"}, {"error": {"message": "NameError: global name '__' is not defined", "traceback": [{"linenr": 329, "function": "run", "line": "testMethod()", "filename": "/usr/local/Cellar/python/2.7.12/Frameworks/Python.framework/Versions/2.7/lib/python2.7/unittest/case.py"}, {"linenr": 42, "function": "test_you_can_also_access_the_value_out_using_getattr_and_dict", "line": "self.assertEqual(__, getattr(fido, \"_name\"))", "filename": "/Users/ops/Projects/PyKata/test/test_classes.py"}]}, "result": "error", "name": "test_you_can_also_access_the_value_out_using_getattr_and_dict"}], "nr_error": 15, "nr_success": 0, "name": "test.test_classes.AboutClasses", "nr_failed": 0}, {"testcases": [{"error": {"message": "NameError: global name '__' is not defined", "traceback": [{"linenr": 329, "function": "run", "line": "testMethod()", "filename": "/usr/local/Cellar/python/2.7.12/Frameworks/Python.framework/Versions/2.7/lib/python2.7/unittest/case.py"}, {"linenr": 58, "function": "test_creating_a_dictionary_with_dictionary_comprehension", "line": "self.assertEqual(__, 'first' in dict_comprehension)", "filename": "/Users/ops/Projects/PyKata/test/test_comprehension.py"}]}, "result": "error", "name": "test_creating_a_dictionary_with_dictionary_comprehension"}, {"error": {"message": "NameError: global name '__' is not defined", "traceback": [{"linenr": 329, "function": "run", "line": "testMethod()", "filename": "/usr/local/Cellar/python/2.7.12/Frameworks/Python.framework/Versions/2.7/lib/python2.7/unittest/case.py"}, {"linenr": 49, "function": "test_creating_a_set_with_set_comprehension", "line": "self.assertEqual(__, comprehension)  # rememeber that set members are unique", "filename": "/Users/ops/Projects/PyKata/test/test_comprehension.py"}]}, "result": "error", "name": "test_creating_a_set_with_set_comprehension"}, {"error": {"message": "NameError: global name '__' is not defined", "traceback": [{"linenr": 329, "function": "run", "line": "testMethod()", "filename": "/usr/local/Cellar/python/2.7.12/Frameworks/Python.framework/Versions/2.7/lib/python2.7/unittest/case.py"}, {"linenr": 16, "function": "test_creating_lists_with_list_comprehensions", "line": "self.assertEqual(__, comprehension[0])", "filename": "/Users/ops/Projects/PyKata/test/test_comprehension.py"}]}, "result": "error", "name": "test_creating_lists_with_list_comprehensions"}, {"error": {"message": "NameError: global name '__' is not defined", "traceback": [{"linenr": 329, "function": "run", "line": "testMethod()", "filename": "/usr/local/Cellar/python/2.7.12/Frameworks/Python.framework/Versions/2.7/lib/python2.7/unittest/case.py"}, {"linenr": 43, "function": "test_double_list_comprehension", "line": "self.assertEqual(__, len(comprehension))", "filename": "/Users/ops/Projects/PyKata/test/test_comprehension.py"}]}, "result": "error", "name": "test_double_list_comprehension"}, {"error": {"message": "NameError: global name '__' is not defined", "traceback": [{"linenr": 329, "function": "run", "line": "testMethod()", "filename": "/usr/local/Cellar/python/2.7.12/Frameworks/Python.framework/Versions/2.7/lib/python2.7/unittest/case.py"}, {"linenr": 25, "function": "test_filtering_lists_with_list_comprehensions", "line": "self.assertEqual(__, len(feast))", "filename": "/Users/ops/Projects/PyKata/test/test_comprehension.py"}]}, "result": "error", "name": "test_filtering_lists_with_list_comprehensions"}, {"error": {"message": "NameError: global name '__' is not defined", "traceback": [{"linenr": 329, "function": "run", "line": "testMethod()", "filename": "/usr/local/Cellar/python/2.7.12/Frameworks/Python.framework/Versions/2.7/lib/python2.7/unittest/case.py"}, {"linenr": 32, "function": "test_unpacking_tuples_in_list_comprehensions", "line": "self.assertEqual(__, comprehension[0])", "filename": "/Users/ops/Projects/PyKata/test/test_comprehension.py"}]}, "result": "error", "name": "test_unpacking_tuples_in_list_comprehensions"}], "nr_error": 6, "nr_success": 0, "name": "test.test_comprehension.AboutComprehension", "nr_failed": 0}, {"testcases": [{"error": {"message": "NameError: global name '__' is not defined", "traceback": [{"linenr": 329, "function": "run", "line": "testMethod()", "filename": "/usr/local/Cellar/python/2.7.12/Frameworks/Python.framework/Versions/2.7/lib/python2.7/unittest/case.py"}, {"linenr": 46, "function": "test_break_statement", "line": "self.assertEqual(__, result)", "filename": "/Users/ops/Projects/PyKata/test/test_control_statements.py"}]}, "result": "error", "name": "test_break_statement"}, {"error": {"message": "NameError: global name '__' is not defined", "traceback": [{"linenr": 329, "function": "run", "line": "testMethod()", "filename": "/usr/local/Cellar/python/2.7.12/Frameworks/Python.framework/Versions/2.7/lib/python2.7/unittest/case.py"}, {"linenr": 55, "function": "test_continue_statement", "line": "self.assertEqual(__, result)", "filename": "/Users/ops/Projects/PyKata/test/test_control_statements.py"}]}, "result": "error", "name": "test_continue_statement"}, {"error": {"message": "NameError: global name '__' is not defined", "traceback": [{"linenr": 329, "function": "run", "line": "testMethod()", "filename": "/usr/local/Cellar/python/2.7.12/Frameworks/Python.framework/Versions/2.7/lib/python2.7/unittest/case.py"}, {"linenr": 62, "function": "test_for_statement", "line": "self.assertEqual([__, __, __], result)", "filename": "/Users/ops/Projects/PyKata/test/test_control_statements.py"}]}, "result": "error", "name": "test_for_statement"}, {"error": {"message": "NameError: global name '__' is not defined", "traceback": [{"linenr": 329, "function": "run", "line": "testMethod()", "filename": "/usr/local/Cellar/python/2.7.12/Frameworks/Python.framework/Versions/2.7/lib/python2.7/unittest/case.py"}, {"linenr": 76, "function": "test_for_statement_with_tuples", "line": "text = __", "filename": "/Users/ops/Projects/PyKata/test/test_control_statements.py"}]}, "result": "error", "name": "test_for_statement_with_tuples"}, {"error": {"message": "NameError: global name '__' is not defined", "traceback": [{"linenr": 329, "function": "run", "line": "testMethod()", "filename": "/usr/local/Cellar/python/2.7.12/Frameworks/Python.framework/Versions/2.7/lib/python2.7/unittest/case.py"}, {"linenr": 29, "function": "test_if_then_elif_else_statements", "line": "self.assertEqual(__, result)", "filename": "/Users/ops/Projects/PyKata/test/test_control_statements.py"}]}, "result": "error", "name": "test_if_then_elif_else_statements"}, {"error": {"message": "NameError: global name '__' is not defined", "traceback": [{"linenr": 329, "function": "run", "line": "testMethod()", "filename": "/usr/local/Cellar/python/2.7.12/Frameworks/Python.framework/Versions/2.7/lib/python2.7/unittest/case.py"}, {"linenr": 14, "function": "test_if_then_else_statements", "line": "self.assertEqual(__, result)", "filename": "/Users/ops/Projects/PyKata/test/test_control_statements.py"}]}, "result": "error", "name": "test_if_then_else_statements"}, {"error": {"message": "NameError: global name '__' is not defined", "traceback": [{"linenr": 329, "function": "run", "line": "testMethod()", "filename": "/usr/local/Cellar/python/2.7.12/Frameworks/Python.framework/Versions/2.7/lib/python2.7/unittest/case.py"}, {"linenr": 20, "function": "test_if_then_statements", "line": "self.assertEqual(__, result)", "filename": "/Users/ops/Projects/PyKata/test/test_control_statements.py"}]}, "result": "error", "name": "test_if_then_statements"}, {"error": {"message": "NameError: global name '__' is not defined", "traceback": [{"linenr": 329, "function": "run", "line": "testMethod()", "filename": "/usr/local/Cellar/python/2.7.12/Frameworks/Python.framework/Versions/2.7/lib/python2.7/unittest/case.py"}, {"linenr": 37, "function": "test_while_statement", "line": "self.assertEqual(__, result)", "filename": "/Users/ops/Projects/PyKata/test/test_control_statements.py"}]}, "result": "error", "name": "test_while_statement"}], "nr_error": 8, "nr_success": 0, "name": "test.test_control_statements.AboutControlStatements", "nr_failed": 0}, {"testcases": [{"error": {"message": "NameError: global name '__' is not defined", "traceback": [{"linenr": 329, "function": "run", "line": "testMethod()", "filename": "/usr/local/Cellar/python/2.7.12/Frameworks/Python.framework/Versions/2.7/lib/python2.7/unittest/case.py"}, {"linenr": 113, "function": "test_decorator_with_an_argument", "line": "self.assertEqual(__, self.count_badly(2))", "filename": "/Users/ops/Projects/PyKata/test/test_decorating_with_classes.py"}]}, "result": "error", "name": "test_decorator_with_an_argument"}, {"error": {"message": "NameError: global name '__' is not defined", "traceback": [{"linenr": 329, "function": "run", "line": "testMethod()", "filename": "/usr/local/Cellar/python/2.7.12/Frameworks/Python.framework/Versions/2.7/lib/python2.7/unittest/case.py"}, {"linenr": 68, "function": "test_decorator_with_no_arguments", "line": "self.assertEqual(__, self.foo())", "filename": "/Users/ops/Projects/PyKata/test/test_decorating_with_classes.py"}]}, "result": "error", "name": "test_decorator_with_no_arguments"}, {"error": {"message": "NameError: global name '__' is not defined", "traceback": [{"linenr": 329, "function": "run", "line": "testMethod()", "filename": "/usr/local/Cellar/python/2.7.12/Frameworks/Python.framework/Versions/2.7/lib/python2.7/unittest/case.py"}, {"linenr": 117, "function": "test_documentor_which_already_has_a_docstring", "line": "self.assertEqual(__, self.idler.__doc__)", "filename": "/Users/ops/Projects/PyKata/test/test_decorating_with_classes.py"}]}, "result": "error", "name": "test_documentor_which_already_has_a_docstring"}, {"error": {"message": "NameError: global name '__' is not defined", "traceback": [{"linenr": 329, "function": "run", "line": "testMethod()", "filename": "/usr/local/Cellar/python/2.7.12/Frameworks/Python.framework/Versions/2.7/lib/python2.7/unittest/case.py"}, {"linenr": 36, "function": "test_partial_that_wrappers_all_args", "line": "self.assertEqual(__, always99())", "filename": "/Users/ops/Projects/PyKata/test/test_decorating_with_classes.py"}]}, "result": "error", "name": "test_partial_that_wrappers_all_args"}, {"error": {"message": "NameError: global name '__' is not defined", "traceback": [{"linenr": 329, "function": "run", "line": "testMethod()", "filename": "/usr/local/Cellar/python/2.7.12/Frameworks/Python.framework/Versions/2.7/lib/python2.7/unittest/case.py"}, {"linenr": 29, "function": "test_partial_that_wrappers_first_arg", "line": "self.assertEqual(__, max0(-4))", "filename": "/Users/ops/Projects/PyKata/test/test_decorating_with_classes.py"}]}, "result": "error", "name": "test_partial_that_wrappers_first_arg"}, {"error": {"message": "NameError: global name '__' is not defined", "traceback": [{"linenr": 329, "function": "run", "line": "testMethod()", "filename": "/usr/local/Cellar/python/2.7.12/Frameworks/Python.framework/Versions/2.7/lib/python2.7/unittest/case.py"}, {"linenr": 23, "function": "test_partial_that_wrappers_no_args", "line": "self.assertEqual(__, max(7, 23))", "filename": "/Users/ops/Projects/PyKata/test/test_decorating_with_classes.py"}]}, "result": "error", "name": "test_partial_that_wrappers_no_args"}, {"error": {"message": "NameError: global name '__' is not defined", "traceback": [{"linenr": 329, "function": "run", "line": "testMethod()", "filename": "/usr/local/Cellar/python/2.7.12/Frameworks/Python.framework/Versions/2.7/lib/python2.7/unittest/case.py"}, {"linenr": 128, "function": "test_we_can_chain_decorators", "line": "self.assertEqual(__, self.homer())", "filename": "/Users/ops/Projects/PyKata/test/test_decorating_with_classes.py"}]}, "result": "error", "name": "test_we_can_chain_decorators"}, {"error": {"message": "NameError: global name '__' is not defined", "traceback": [{"linenr": 329, "function": "run", "line": "testMethod()", "filename": "/usr/local/Cellar/python/2.7.12/Frameworks/Python.framework/Versions/2.7/lib/python2.7/unittest/case.py"}, {"linenr": 81, "function": "test_what_a_decorator_is_doing_to_a_function", "line": "self.assertEqual(__, self.sound_check())", "filename": "/Users/ops/Projects/PyKata/test/test_decorating_with_classes.py"}]}, "result": "error", "name": "test_what_a_decorator_is_doing_to_a_function"}], "nr_error": 8, "nr_success": 0, "name": "test.test_decorating_with_classes.AboutDecoratingWithClasses", "nr_failed": 0}, {"testcases": [{"error": {"message": "NameError: global name '__' is not defined", "traceback": [{"linenr": 329, "function": "run", "line": "testMethod()", "filename": "/usr/local/Cellar/python/2.7.12/Frameworks/Python.framework/Versions/2.7/lib/python2.7/unittest/case.py"}, {"linenr": 32, "function": "test_decorators_can_change_a_function_output", "line": "self.assertEqual(__, self.render_tag('llama'))", "filename": "/Users/ops/Projects/PyKata/test/test_decorating_with_functions.py"}]}, "result": "error", "name": "test_decorators_can_change_a_function_output"}, {"error": {"message": "AttributeError: 'AboutDecoratingWithFunctions' object has no attribute 'assertMatch'", "traceback": [{"linenr": 329, "function": "run", "line": "testMethod()", "filename": "/usr/local/Cellar/python/2.7.12/Frameworks/Python.framework/Versions/2.7/lib/python2.7/unittest/case.py"}, {"linenr": 17, "function": "test_decorators_can_modify_a_function", "line": "self.assertMatch(__, self.mediocre_song())", "filename": "/Users/ops/Projects/PyKata/test/test_decorating_with_functions.py"}]}, "result": "error", "name": "test_decorators_can_modify_a_function"}], "nr_error": 2, "nr_success": 0, "name": "test.test_decorating_with_functions.AboutDecoratingWithFunctions", "nr_failed": 0}, {"testcases": [{"error": {"message": "NameError: global name '__' is not defined", "traceback": [{"linenr": 329, "function": "run", "line": "testMethod()", "filename": "/usr/local/Cellar/python/2.7.12/Frameworks/Python.framework/Versions/2.7/lib/python2.7/unittest/case.py"}, {"linenr": 111, "function": "test_another_way_to_make_a_deletable_property", "line": "self.assertEqual(__, citizen.name)", "filename": "/Users/ops/Projects/PyKata/test/test_deleting_objects.py"}]}, "result": "error", "name": "test_another_way_to_make_a_deletable_property"}, {"error": {"message": "AttributeError: 'AboutDeletingObjects' object has no attribute 'assertMatch'", "traceback": [{"linenr": 329, "function": "run", "line": "testMethod()", "filename": "/usr/local/Cellar/python/2.7.12/Frameworks/Python.framework/Versions/2.7/lib/python2.7/unittest/case.py"}, {"linenr": 55, "function": "test_del_can_remove_attributes", "line": "self.assertMatch(__, err_msg1)", "filename": "/Users/ops/Projects/PyKata/test/test_deleting_objects.py"}]}, "result": "error", "name": "test_del_can_remove_attributes"}, {"error": {"message": "AttributeError: 'AboutDeletingObjects' object has no attribute 'assertMatch'", "traceback": [{"linenr": 329, "function": "run", "line": "testMethod()", "filename": "/usr/local/Cellar/python/2.7.12/Frameworks/Python.framework/Versions/2.7/lib/python2.7/unittest/case.py"}, {"linenr": 22, "function": "test_del_can_remove_entire_lists", "line": "self.assertMatch(__, e[0])", "filename": "/Users/ops/Projects/PyKata/test/test_deleting_objects.py"}]}, "result": "error", "name": "test_del_can_remove_entire_lists"}, {"error": {"message": "NameError: global name '__' is not defined", "traceback": [{"linenr": 329, "function": "run", "line": "testMethod()", "filename": "/usr/local/Cellar/python/2.7.12/Frameworks/Python.framework/Versions/2.7/lib/python2.7/unittest/case.py"}, {"linenr": 13, "function": "test_del_can_remove_slices", "line": "self.assertEqual(__, lottery_nums)", "filename": "/Users/ops/Projects/PyKata/test/test_deleting_objects.py"}]}, "result": "error", "name": "test_del_can_remove_slices"}, {"error": {"message": "NameError: global name '__' is not defined", "traceback": [{"linenr": 329, "function": "run", "line": "testMethod()", "filename": "/usr/local/Cellar/python/2.7.12/Frameworks/Python.framework/Versions/2.7/lib/python2.7/unittest/case.py"}, {"linenr": 85, "function": "test_del_works_with_properties", "line": "self.assertEqual(__, cowboy.name)", "filename": "/Users/ops/Projects/PyKata/test/test_deleting_objects.py"}]}, "result": "error", "name": "test_del_works_with_properties"}, {"error": {"message": "NameError: global name '__' is not defined", "traceback": [{"linenr": 329, "function": "run", "line": "testMethod()", "filename": "/usr/local/Cellar/python/2.7.12/Frameworks/Python.framework/Versions/2.7/lib/python2.7/unittest/case.py"}, {"linenr": 127, "function": "tests_del_can_be_overriden", "line": "self.assertEqual(__, sale.last_deletion)", "filename": "/Users/ops/Projects/PyKata/test/test_deleting_objects.py"}]}, "result": "error", "name": "tests_del_can_be_overriden"}], "nr_error": 6, "nr_success": 0, "name": "test.test_deleting_objects.AboutDeletingObjects", "nr_failed": 0}, {"testcases": [{"result": "success", "name": "test_can_create_a_dice_set"}, {"result": "success", "name": "test_dice_values_do_not_change_unless_explicitly_rolled"}, {"error": {"message": "AssertionError: Two rolls should not be equal", "traceback": [{"linenr": 329, "function": "run", "line": "testMethod()", "filename": "/usr/local/Cellar/python/2.7.12/Frameworks/Python.framework/Versions/2.7/lib/python2.7/unittest/case.py"}, {"linenr": 56, "function": "test_dice_values_should_change_between_rolls", "line": "\"Two rolls should not be equal\")", "filename": "/Users/ops/Projects/PyKata/test/test_dice_project.py"}, {"linenr": 522, "function": "assertNotEqual", "line": "raise self.failureException(msg)", "filename": "/usr/local/Cellar/python/2.7.12/Frameworks/Python.framework/Versions/2.7/lib/python2.7/unittest/case.py"}]}, "result": "failed", "name": "test_dice_values_should_change_between_rolls"}, {"error": {"message": "AssertionError: should be a list", "traceback": [{"linenr": 329, "function": "run", "line": "testMethod()", "filename": "/usr/local/Cellar/python/2.7.12/Frameworks/Python.framework/Versions/2.7/lib/python2.7/unittest/case.py"}, {"linenr": 32, "function": "test_rolling_the_dice_returns_a_set_of_integers_between_1_and_6", "line": "self.assertTrue(isinstance(dice.values, list), \"should be a list\")", "filename": "/Users/ops/Projects/PyKata/test/test_dice_project.py"}, {"linenr": 422, "function": "assertTrue", "line": "raise self.failureException(msg)", "filename": "/usr/local/Cellar/python/2.7.12/Frameworks/Python.framework/Versions/2.7/lib/python2.7/unittest/case.py"}]}, "result": "failed", "name": "test_rolling_the_dice_returns_a_set_of_integers_between_1_and_6"}, {"error": {"message": "TypeError: object of type 'NoneType' has no len()", "traceback": [{"linenr": 329, "function": "run", "line": "testMethod()", "filename": "/usr/local/Cellar/python/2.7.12/Frameworks/Python.framework/Versions/2.7/lib/python2.7/unittest/case.py"}, {"linenr": 68, "function": "test_you_can_roll_different_numbers_of_dice", "line": "self.assertEqual(3, len(dice.values))", "filename": "/Users/ops/Projects/PyKata/test/test_dice_project.py"}]}, "result": "error", "name": "test_you_can_roll_different_numbers_of_dice"}], "nr_error": 1, "nr_success": 2, "name": "test.test_dice_project.AboutDiceProject", "nr_failed": 2}, {"testcases": [{"error": {"message": "NameError: global name '__' is not defined", "traceback": [{"linenr": 329, "function": "run", "line": "testMethod()", "filename": "/usr/local/Cellar/python/2.7.12/Frameworks/Python.framework/Versions/2.7/lib/python2.7/unittest/case.py"}, {"linenr": 26, "function": "test_accessing_dictionaries", "line": "self.assertEqual(__, babel_fish['one'])", "filename": "/Users/ops/Projects/PyKata/test/test_dictionaries.py"}]}, "result": "error", "name": "test_accessing_dictionaries"}, {"error": {"message": "NameError: global name '__' is not defined", "traceback": [{"linenr": 329, "function": "run", "line": "testMethod()", "filename": "/usr/local/Cellar/python/2.7.12/Frameworks/Python.framework/Versions/2.7/lib/python2.7/unittest/case.py"}, {"linenr": 33, "function": "test_changing_dictionaries", "line": "expected = {'two': 'dos', 'one': __}", "filename": "/Users/ops/Projects/PyKata/test/test_dictionaries.py"}]}, "result": "error", "name": "test_changing_dictionaries"}, {"error": {"message": "NameError: global name '__' is not defined", "traceback": [{"linenr": 329, "function": "run", "line": "testMethod()", "filename": "/usr/local/Cellar/python/2.7.12/Frameworks/Python.framework/Versions/2.7/lib/python2.7/unittest/case.py"}, {"linenr": 16, "function": "test_creating_dictionaries", "line": "self.assertEqual(__, len(empty_dict))", "filename": "/Users/ops/Projects/PyKata/test/test_dictionaries.py"}]}, "result": "error", "name": "test_creating_dictionaries"}, {"error": {"message": "NameError: global name '____' is not defined", "traceback": [{"linenr": 329, "function": "run", "line": "testMethod()", "filename": "/usr/local/Cellar/python/2.7.12/Frameworks/Python.framework/Versions/2.7/lib/python2.7/unittest/case.py"}, {"linenr": 40, "function": "test_dictionary_is_unordered", "line": "self.assertEqual(____, dict1 == dict2)", "filename": "/Users/ops/Projects/PyKata/test/test_dictionaries.py"}]}, "result": "error", "name": "test_dictionary_is_unordered"}, {"error": {"message": "NameError: global name '__' is not defined", "traceback": [{"linenr": 329, "function": "run", "line": "testMethod()", "filename": "/usr/local/Cellar/python/2.7.12/Frameworks/Python.framework/Versions/2.7/lib/python2.7/unittest/case.py"}, {"linenr": 44, "function": "test_dictionary_keys_and_values", "line": "self.assertEqual(__, len(babel_fish.keys()))", "filename": "/Users/ops/Projects/PyKata/test/test_dictionaries.py"}]}, "result": "error", "name": "test_dictionary_keys_and_values"}, {"error": {"message": "NameError: global name '__' is not defined", "traceback": [{"linenr": 329, "function": "run", "line": "testMethod()", "filename": "/usr/local/Cellar/python/2.7.12/Frameworks/Python.framework/Versions/2.7/lib/python2.7/unittest/case.py"}, {"linenr": 22, "function": "test_dictionary_literals", "line": "self.assertEqual(__, len(babel_fish))", "filename": "/Users/ops/Projects/PyKata/test/test_dictionaries.py"}]}, "result": "error", "name": "test_dictionary_literals"}, {"error": {"message": "NameError: global name '__' is not defined", "traceback": [{"linenr": 329, "function": "run", "line": "testMethod()", "filename": "/usr/local/Cellar/python/2.7.12/Frameworks/Python.framework/Versions/2.7/lib/python2.7/unittest/case.py"}, {"linenr": 57, "function": "test_making_a_dictionary_from_a_sequence_of_keys", "line": "self.assertEqual(__, len(cards))", "filename": "/Users/ops/Projects/PyKata/test/test_dictionaries.py"}]}, "result": "error", "name": "test_making_a_dictionary_from_a_sequence_of_keys"}], "nr_error": 7, "nr_success": 0, "name": "test.test_dictionaries.AboutDictionaries", "nr_failed": 0}, {"testcases": [{"error": {"message": "NameError: global name '__' is not defined", "traceback": [{"linenr": 329, "function": "run", "line": "testMethod()", "filename": "/usr/local/Cellar/python/2.7.12/Frameworks/Python.framework/Versions/2.7/lib/python2.7/unittest/case.py"}, {"linenr": 56, "function": "test_else_clause", "line": "self.assertEqual(__, result)", "filename": "/Users/ops/Projects/PyKata/test/test_exceptions.py"}]}, "result": "error", "name": "test_else_clause"}, {"error": {"message": "NameError: global name '__' is not defined", "traceback": [{"linenr": 329, "function": "run", "line": "testMethod()", "filename": "/usr/local/Cellar/python/2.7.12/Frameworks/Python.framework/Versions/2.7/lib/python2.7/unittest/case.py"}, {"linenr": 14, "function": "test_exceptions_inherit_from_exception", "line": "self.assertEqual(__, mro[1].__name__)", "filename": "/Users/ops/Projects/PyKata/test/test_exceptions.py"}]}, "result": "error", "name": "test_exceptions_inherit_from_exception"}, {"error": {"message": "NameError: global name '__' is not defined", "traceback": [{"linenr": 329, "function": "run", "line": "testMethod()", "filename": "/usr/local/Cellar/python/2.7.12/Frameworks/Python.framework/Versions/2.7/lib/python2.7/unittest/case.py"}, {"linenr": 68, "function": "test_finally_clause", "line": "self.assertEqual(__, result)", "filename": "/Users/ops/Projects/PyKata/test/test_exceptions.py"}]}, "result": "error", "name": "test_finally_clause"}, {"error": {"message": "NameError: global name '__' is not defined", "traceback": [{"linenr": 329, "function": "run", "line": "testMethod()", "filename": "/usr/local/Cellar/python/2.7.12/Frameworks/Python.framework/Versions/2.7/lib/python2.7/unittest/case.py"}, {"linenr": 43, "function": "test_raising_a_specific_error", "line": "self.assertEqual(__, result)", "filename": "/Users/ops/Projects/PyKata/test/test_exceptions.py"}]}, "result": "error", "name": "test_raising_a_specific_error"}, {"error": {"message": "NameError: global name '__' is not defined", "traceback": [{"linenr": 329, "function": "run", "line": "testMethod()", "filename": "/usr/local/Cellar/python/2.7.12/Frameworks/Python.framework/Versions/2.7/lib/python2.7/unittest/case.py"}, {"linenr": 26, "function": "test_try_clause", "line": "self.assertEqual(__, result)", "filename": "/Users/ops/Projects/PyKata/test/test_exceptions.py"}]}, "result": "error", "name": "test_try_clause"}], "nr_error": 5, "nr_success": 0, "name": "test.test_exceptions.AboutExceptions", "nr_failed": 0}, {"testcases": [{"result": "success", "name": "test_extra_credit_task"}], "nr_error": 0, "nr_success": 1, "name": "test.test_extra_credit.AboutExtraCredit", "nr_failed": 0}, {"testcases": [{"error": {"message": "AttributeError: 'AboutGenerators' object has no attribute 'assertMatch'", "traceback": [{"linenr": 329, "function": "run", "line": "testMethod()", "filename": "/usr/local/Cellar/python/2.7.12/Frameworks/Python.framework/Versions/2.7/lib/python2.7/unittest/case.py"}, {"linenr": 116, "function": "test_before_sending_a_value_to_a_generator_next_must_be_called", "line": "self.assertMatch(__, ex[0])", "filename": "/Users/ops/Projects/PyKata/test/test_generators.py"}]}, "result": "error", "name": "test_before_sending_a_value_to_a_generator_next_must_be_called"}, {"error": {"message": "NameError: global name '__' is not defined", "traceback": [{"linenr": 329, "function": "run", "line": "testMethod()", "filename": "/usr/local/Cellar/python/2.7.12/Frameworks/Python.framework/Versions/2.7/lib/python2.7/unittest/case.py"}, {"linenr": 22, "function": "test_generating_values_on_the_fly", "line": "self.assertEqual(__, result)", "filename": "/Users/ops/Projects/PyKata/test/test_generators.py"}]}, "result": "error", "name": "test_generating_values_on_the_fly"}, {"error": {"message": "NameError: global name '__' is not defined", "traceback": [{"linenr": 329, "function": "run", "line": "testMethod()", "filename": "/usr/local/Cellar/python/2.7.12/Frameworks/Python.framework/Versions/2.7/lib/python2.7/unittest/case.py"}, {"linenr": 46, "function": "test_generator_expressions_are_a_one_shot_deal", "line": "self.assertEqual(__, attempt1)", "filename": "/Users/ops/Projects/PyKata/test/test_generators.py"}]}, "result": "error", "name": "test_generator_expressions_are_a_one_shot_deal"}, {"error": {"message": "NameError: global name '__' is not defined", "traceback": [{"linenr": 329, "function": "run", "line": "testMethod()", "filename": "/usr/local/Cellar/python/2.7.12/Frameworks/Python.framework/Versions/2.7/lib/python2.7/unittest/case.py"}, {"linenr": 90, "function": "test_generator_keeps_track_of_local_variables", "line": "self.assertEqual(__, list(result))", "filename": "/Users/ops/Projects/PyKata/test/test_generators.py"}]}, "result": "error", "name": "test_generator_keeps_track_of_local_variables"}, {"error": {"message": "NameError: global name '__' is not defined", "traceback": [{"linenr": 329, "function": "run", "line": "testMethod()", "filename": "/usr/local/Cellar/python/2.7.12/Frameworks/Python.framework/Versions/2.7/lib/python2.7/unittest/case.py"}, {"linenr": 61, "function": "test_generator_method_will_yield_values_during_iteration", "line": "self.assertEqual(__, result)", "filename": "/Users/ops/Projects/PyKata/test/test_generators.py"}]}, "result": "error", "name": "test_generator_method_will_yield_values_during_iteration"}, {"error": {"message": "NameError: global name '__' is not defined", "traceback": [{"linenr": 329, "function": "run", "line": "testMethod()", "filename": "/usr/local/Cellar/python/2.7.12/Frameworks/Python.framework/Versions/2.7/lib/python2.7/unittest/case.py"}, {"linenr": 77, "function": "test_generator_method_with_parameter", "line": "self.assertEqual(__, list(result))", "filename": "/Users/ops/Projects/PyKata/test/test_generators.py"}]}, "result": "error", "name": "test_generator_method_with_parameter"}, {"error": {"message": "NameError: global name '__' is not defined", "traceback": [{"linenr": 329, "function": "run", "line": "testMethod()", "filename": "/usr/local/Cellar/python/2.7.12/Frameworks/Python.framework/Versions/2.7/lib/python2.7/unittest/case.py"}, {"linenr": 31, "function": "test_generators_are_different_to_list_comprehensions", "line": "self.assertEqual(__, list(num_generator)[0])", "filename": "/Users/ops/Projects/PyKata/test/test_generators.py"}]}, "result": "error", "name": "test_generators_are_different_to_list_comprehensions"}, {"error": {"message": "NameError: global name '__' is not defined", "traceback": [{"linenr": 329, "function": "run", "line": "testMethod()", "filename": "/usr/local/Cellar/python/2.7.12/Frameworks/Python.framework/Versions/2.7/lib/python2.7/unittest/case.py"}, {"linenr": 108, "function": "test_generators_can_act_as_coroutines", "line": "self.assertEqual(__, generator.send(1 + 2))", "filename": "/Users/ops/Projects/PyKata/test/test_generators.py"}]}, "result": "error", "name": "test_generators_can_act_as_coroutines"}, {"error": {"message": "NameError: global name '__' is not defined", "traceback": [{"linenr": 329, "function": "run", "line": "testMethod()", "filename": "/usr/local/Cellar/python/2.7.12/Frameworks/Python.framework/Versions/2.7/lib/python2.7/unittest/case.py"}, {"linenr": 65, "function": "test_generators_can_be_manually_iterated_and_closed", "line": "self.assertEqual(__, next(result))", "filename": "/Users/ops/Projects/PyKata/test/test_generators.py"}]}, "result": "error", "name": "test_generators_can_be_manually_iterated_and_closed"}, {"error": {"message": "NameError: global name '__' is not defined", "traceback": [{"linenr": 329, "function": "run", "line": "testMethod()", "filename": "/usr/local/Cellar/python/2.7.12/Frameworks/Python.framework/Versions/2.7/lib/python2.7/unittest/case.py"}, {"linenr": 134, "function": "test_generators_can_see_if_they_have_been_called_with_a_value", "line": "self.assertEqual(__, next(generator2))", "filename": "/Users/ops/Projects/PyKata/test/test_generators.py"}]}, "result": "error", "name": "test_generators_can_see_if_they_have_been_called_with_a_value"}, {"error": {"message": "NameError: global name '__' is not defined", "traceback": [{"linenr": 329, "function": "run", "line": "testMethod()", "filename": "/usr/local/Cellar/python/2.7.12/Frameworks/Python.framework/Versions/2.7/lib/python2.7/unittest/case.py"}, {"linenr": 141, "function": "test_send_none_is_equivalent_to_next", "line": "self.assertEqual(__, generator.send(None))", "filename": "/Users/ops/Projects/PyKata/test/test_generators.py"}]}, "result": "error", "name": "test_send_none_is_equivalent_to_next"}, {"result": "success", "name": "yield_tester"}], "nr_error": 11, "nr_success": 1, "name": "test.test_generators.AboutGenerators", "nr_failed": 0}, {"testcases": [{"error": {"message": "AttributeError: 'AboutInheritance' object has no attribute 'assertMatch'", "traceback": [{"linenr": 329, "function": "run", "line": "testMethod()", "filename": "/usr/local/Cellar/python/2.7.12/Frameworks/Python.framework/Versions/2.7/lib/python2.7/unittest/case.py"}, {"linenr": 88, "function": "test_base_init_does_not_get_called_automatically", "line": "self.assertMatch(__, ex[0])", "filename": "/Users/ops/Projects/PyKata/test/test_inheritance.py"}]}, "result": "error", "name": "test_base_init_does_not_get_called_automatically"}, {"error": {"message": "NameError: global name '__' is not defined", "traceback": [{"linenr": 329, "function": "run", "line": "testMethod()", "filename": "/usr/local/Cellar/python/2.7.12/Frameworks/Python.framework/Versions/2.7/lib/python2.7/unittest/case.py"}, {"linenr": 92, "function": "test_base_init_has_to_be_called_explicitly", "line": "self.assertEqual(__, boxer.name)", "filename": "/Users/ops/Projects/PyKata/test/test_inheritance.py"}]}, "result": "error", "name": "test_base_init_has_to_be_called_explicitly"}, {"error": {"message": "NameError: global name '__' is not defined", "traceback": [{"linenr": 329, "function": "run", "line": "testMethod()", "filename": "/usr/local/Cellar/python/2.7.12/Frameworks/Python.framework/Versions/2.7/lib/python2.7/unittest/case.py"}, {"linenr": 34, "function": "test_instances_inherit_behavior_from_parent_class", "line": "self.assertEqual(__, chico.name)", "filename": "/Users/ops/Projects/PyKata/test/test_inheritance.py"}]}, "result": "error", "name": "test_instances_inherit_behavior_from_parent_class"}, {"error": {"message": "NameError: global name '__' is not defined", "traceback": [{"linenr": 329, "function": "run", "line": "testMethod()", "filename": "/usr/local/Cellar/python/2.7.12/Frameworks/Python.framework/Versions/2.7/lib/python2.7/unittest/case.py"}, {"linenr": 38, "function": "test_subclasses_add_new_behavior", "line": "self.assertEqual(__, chico.wag())", "filename": "/Users/ops/Projects/PyKata/test/test_inheritance.py"}]}, "result": "error", "name": "test_subclasses_add_new_behavior"}, {"error": {"message": "NameError: global name '__' is not defined", "traceback": [{"linenr": 329, "function": "run", "line": "testMethod()", "filename": "/usr/local/Cellar/python/2.7.12/Frameworks/Python.framework/Versions/2.7/lib/python2.7/unittest/case.py"}, {"linenr": 61, "function": "test_subclasses_can_invoke_parent_behavior_via_super", "line": "self.assertEqual(__, ralph.bark())", "filename": "/Users/ops/Projects/PyKata/test/test_inheritance.py"}]}, "result": "error", "name": "test_subclasses_can_invoke_parent_behavior_via_super"}, {"error": {"message": "NameError: global name '__' is not defined", "traceback": [{"linenr": 329, "function": "run", "line": "testMethod()", "filename": "/usr/local/Cellar/python/2.7.12/Frameworks/Python.framework/Versions/2.7/lib/python2.7/unittest/case.py"}, {"linenr": 48, "function": "test_subclasses_can_modify_existing_behavior", "line": "self.assertEqual(__, chico.bark())", "filename": "/Users/ops/Projects/PyKata/test/test_inheritance.py"}]}, "result": "error", "name": "test_subclasses_can_modify_existing_behavior"}, {"error": {"message": "NameError: global name '____' is not defined", "traceback": [{"linenr": 329, "function": "run", "line": "testMethod()", "filename": "/usr/local/Cellar/python/2.7.12/Frameworks/Python.framework/Versions/2.7/lib/python2.7/unittest/case.py"}, {"linenr": 27, "function": "test_subclasses_have_the_parent_as_an_ancestor", "line": "self.assertEqual(____, issubclass(self.Chihuahua, self.Dog))", "filename": "/Users/ops/Projects/PyKata/test/test_inheritance.py"}]}, "result": "error", "name": "test_subclasses_have_the_parent_as_an_ancestor"}, {"error": {"message": "NameError: global name '__' is not defined", "traceback": [{"linenr": 329, "function": "run", "line": "testMethod()", "filename": "/usr/local/Cellar/python/2.7.12/Frameworks/Python.framework/Versions/2.7/lib/python2.7/unittest/case.py"}, {"linenr": 71, "function": "test_super_works_across_methods", "line": "self.assertEqual(__, george.growl())", "filename": "/Users/ops/Projects/PyKata/test/test_inheritance.py"}]}, "result": "error", "name": "test_super_works_across_methods"}, {"error": {"message": "NameError: global name '____' is not defined", "traceback": [{"linenr": 329, "function": "run", "line": "testMethod()", "filename": "/usr/local/Cellar/python/2.7.12/Frameworks/Python.framework/Versions/2.7/lib/python2.7/unittest/case.py"}, {"linenr": 30, "function": "test_this_subclass_ultimately_inherits_from_object_class", "line": "self.assertEqual(____, issubclass(self.Chihuahua, object))", "filename": "/Users/ops/Projects/PyKata/test/test_inheritance.py"}]}, "result": "error", "name": "test_this_subclass_ultimately_inherits_from_object_class"}], "nr_error": 9, "nr_success": 0, "name": "test.test_inheritance.AboutInheritance", "nr_failed": 0}, {"testcases": [{"error": {"message": "NameError: global name '__' is not defined", "traceback": [{"linenr": 329, "function": "run", "line": "testMethod()", "filename": "/usr/local/Cellar/python/2.7.12/Frameworks/Python.framework/Versions/2.7/lib/python2.7/unittest/case.py"}, {"linenr": 99, "function": "test_all_iteration_methods_work_on_any_sequence_not_just_lists", "line": "self.assertEqual(__, list(result))", "filename": "/Users/ops/Projects/PyKata/test/test_iteration.py"}]}, "result": "error", "name": "test_all_iteration_methods_work_on_any_sequence_not_just_lists"}, {"error": {"message": "NameError: global name '__' is not defined", "traceback": [{"linenr": 329, "function": "run", "line": "testMethod()", "filename": "/usr/local/Cellar/python/2.7.12/Frameworks/Python.framework/Versions/2.7/lib/python2.7/unittest/case.py"}, {"linenr": 50, "function": "test_filter_selects_certain_items_from_a_list", "line": "self.assertEqual(__, even_numbers)", "filename": "/Users/ops/Projects/PyKata/test/test_iteration.py"}]}, "result": "error", "name": "test_filter_selects_certain_items_from_a_list"}, {"error": {"message": "NameError: global name '__' is not defined", "traceback": [{"linenr": 329, "function": "run", "line": "testMethod()", "filename": "/usr/local/Cellar/python/2.7.12/Frameworks/Python.framework/Versions/2.7/lib/python2.7/unittest/case.py"}, {"linenr": 23, "function": "test_iterating_with_next", "line": "self.assertEqual(__, next(stages))", "filename": "/Users/ops/Projects/PyKata/test/test_iteration.py"}]}, "result": "error", "name": "test_iterating_with_next"}, {"error": {"message": "NameError: global name '__' is not defined", "traceback": [{"linenr": 329, "function": "run", "line": "testMethod()", "filename": "/usr/local/Cellar/python/2.7.12/Frameworks/Python.framework/Versions/2.7/lib/python2.7/unittest/case.py"}, {"linenr": 17, "function": "test_iterators_are_a_type", "line": "self.assertEqual(__, fib)", "filename": "/Users/ops/Projects/PyKata/test/test_iteration.py"}]}, "result": "error", "name": "test_iterators_are_a_type"}, {"error": {"message": "NameError: global name '__' is not defined", "traceback": [{"linenr": 329, "function": "run", "line": "testMethod()", "filename": "/usr/local/Cellar/python/2.7.12/Frameworks/Python.framework/Versions/2.7/lib/python2.7/unittest/case.py"}, {"linenr": 60, "function": "test_just_return_first_item_found", "line": "self.assertEqual([__], filter(is_big_name, names)[:1])", "filename": "/Users/ops/Projects/PyKata/test/test_iteration.py"}]}, "result": "error", "name": "test_just_return_first_item_found"}, {"error": {"message": "NameError: global name '__' is not defined", "traceback": [{"linenr": 329, "function": "run", "line": "testMethod()", "filename": "/usr/local/Cellar/python/2.7.12/Frameworks/Python.framework/Versions/2.7/lib/python2.7/unittest/case.py"}, {"linenr": 41, "function": "test_map_transforms_elements_of_a_list", "line": "self.assertEqual(__, mapped_seq)", "filename": "/Users/ops/Projects/PyKata/test/test_iteration.py"}]}, "result": "error", "name": "test_map_transforms_elements_of_a_list"}, {"error": {"message": "NameError: global name '__' is not defined", "traceback": [{"linenr": 329, "function": "run", "line": "testMethod()", "filename": "/usr/local/Cellar/python/2.7.12/Frameworks/Python.framework/Versions/2.7/lib/python2.7/unittest/case.py"}, {"linenr": 78, "function": "test_reduce_will_blow_your_mind", "line": "self.assertEqual(__, result)", "filename": "/Users/ops/Projects/PyKata/test/test_iteration.py"}]}, "result": "error", "name": "test_reduce_will_blow_your_mind"}, {"error": {"message": "NameError: global name '__' is not defined", "traceback": [{"linenr": 329, "function": "run", "line": "testMethod()", "filename": "/usr/local/Cellar/python/2.7.12/Frameworks/Python.framework/Versions/2.7/lib/python2.7/unittest/case.py"}, {"linenr": 92, "function": "test_use_pass_for_iterations_with_no_body", "line": "self.assertEqual(__, num)", "filename": "/Users/ops/Projects/PyKata/test/test_iteration.py"}]}, "result": "error", "name": "test_use_pass_for_iterations_with_no_body"}], "nr_error": 8, "nr_success": 0, "name": "test.test_iteration.AboutIteration", "nr_failed": 0}, {"testcases": [{"error": {"message": "NameError: global name '__' is not defined", "traceback": [{"linenr": 329, "function": "run", "line": "testMethod()", "filename": "/usr/local/Cellar/python/2.7.12/Frameworks/Python.framework/Versions/2.7/lib/python2.7/unittest/case.py"}, {"linenr": 25, "function": "test_accessing_lambda_via_assignment", "line": "self.assertEqual(__, sausages(3))", "filename": "/Users/ops/Projects/PyKata/test/test_lambdas.py"}]}, "result": "error", "name": "test_accessing_lambda_via_assignment"}, {"error": {"message": "NameError: global name '__' is not defined", "traceback": [{"linenr": 329, "function": "run", "line": "testMethod()", "filename": "/usr/local/Cellar/python/2.7.12/Frameworks/Python.framework/Versions/2.7/lib/python2.7/unittest/case.py"}, {"linenr": 29, "function": "test_accessing_lambda_without_assignment", "line": "self.assertEqual(__, self.make_order('spam')(39823))", "filename": "/Users/ops/Projects/PyKata/test/test_lambdas.py"}]}, "result": "error", "name": "test_accessing_lambda_without_assignment"}, {"error": {"message": "NameError: global name '__' is not defined", "traceback": [{"linenr": 329, "function": "run", "line": "testMethod()", "filename": "/usr/local/Cellar/python/2.7.12/Frameworks/Python.framework/Versions/2.7/lib/python2.7/unittest/case.py"}, {"linenr": 14, "function": "test_lambdas_can_be_assigned_to_variables_and_called_explicitly", "line": "self.assertEqual(__, add_one(10))", "filename": "/Users/ops/Projects/PyKata/test/test_lambdas.py"}]}, "result": "error", "name": "test_lambdas_can_be_assigned_to_variables_and_called_explicitly"}], "nr_error": 3, "nr_success": 0, "name": "test.test_lambdas.AboutLambdas", "nr_failed": 0}, {"testcases": [{"error": {"message": "NameError: global name '__' is not defined", "traceback": [{"linenr": 329, "function": "run", "line": "testMethod()", "filename": "/usr/local/Cellar/python/2.7.12/Frameworks/Python.framework/Versions/2.7/lib/python2.7/unittest/case.py"}, {"linenr": 14, "function": "test_non_parallel_assignment", "line": "self.assertEqual(__, names)", "filename": "/Users/ops/Projects/PyKata/test/test_list_assignments.py"}]}, "result": "error", "name": "test_non_parallel_assignment"}, {"error": {"message": "NameError: global name '__' is not defined", "traceback": [{"linenr": 329, "function": "run", "line": "testMethod()", "filename": "/usr/local/Cellar/python/2.7.12/Frameworks/Python.framework/Versions/2.7/lib/python2.7/unittest/case.py"}, {"linenr": 18, "function": "test_parallel_assignments", "line": "self.assertEqual(__, first_name)", "filename": "/Users/ops/Projects/PyKata/test/test_list_assignments.py"}]}, "result": "error", "name": "test_parallel_assignments"}, {"error": {"message": "NameError: global name '__' is not defined", "traceback": [{"linenr": 329, "function": "run", "line": "testMethod()", "filename": "/usr/local/Cellar/python/2.7.12/Frameworks/Python.framework/Versions/2.7/lib/python2.7/unittest/case.py"}, {"linenr": 23, "function": "test_parallel_assignments_with_sublists", "line": "self.assertEqual(__, first_name)", "filename": "/Users/ops/Projects/PyKata/test/test_list_assignments.py"}]}, "result": "error", "name": "test_parallel_assignments_with_sublists"}, {"error": {"message": "NameError: global name '__' is not defined", "traceback": [{"linenr": 329, "function": "run", "line": "testMethod()", "filename": "/usr/local/Cellar/python/2.7.12/Frameworks/Python.framework/Versions/2.7/lib/python2.7/unittest/case.py"}, {"linenr": 30, "function": "test_swapping_with_parallel_assignment", "line": "self.assertEqual(__, first_name)", "filename": "/Users/ops/Projects/PyKata/test/test_list_assignments.py"}]}, "result": "error", "name": "test_swapping_with_parallel_assignment"}], "nr_error": 4, "nr_success": 0, "name": "test.test_list_assignments.AboutListAssignments", "nr_failed": 0}, {"testcases": [{"error": {"message": "NameError: global name '__' is not defined", "traceback": [{"linenr": 329, "function": "run", "line": "testMethod()", "filename": "/usr/local/Cellar/python/2.7.12/Frameworks/Python.framework/Versions/2.7/lib/python2.7/unittest/case.py"}, {"linenr": 33, "function": "test_accessing_list_elements", "line": "self.assertEqual(__, noms[0])", "filename": "/Users/ops/Projects/PyKata/test/test_lists.py"}]}, "result": "error", "name": "test_accessing_list_elements"}, {"error": {"message": "NameError: global name '__' is not defined", "traceback": [{"linenr": 329, "function": "run", "line": "testMethod()", "filename": "/usr/local/Cellar/python/2.7.12/Frameworks/Python.framework/Versions/2.7/lib/python2.7/unittest/case.py"}, {"linenr": 15, "function": "test_creating_lists", "line": "self.assertEqual(__, len(empty_list))", "filename": "/Users/ops/Projects/PyKata/test/test_lists.py"}]}, "result": "error", "name": "test_creating_lists"}, {"error": {"message": "NameError: global name '__' is not defined", "traceback": [{"linenr": 329, "function": "run", "line": "testMethod()", "filename": "/usr/local/Cellar/python/2.7.12/Frameworks/Python.framework/Versions/2.7/lib/python2.7/unittest/case.py"}, {"linenr": 70, "function": "test_insertions", "line": "self.assertEqual(__, knight)", "filename": "/Users/ops/Projects/PyKata/test/test_lists.py"}]}, "result": "error", "name": "test_insertions"}, {"error": {"message": "NameError: global name '__' is not defined", "traceback": [{"linenr": 329, "function": "run", "line": "testMethod()", "filename": "/usr/local/Cellar/python/2.7.12/Frameworks/Python.framework/Versions/2.7/lib/python2.7/unittest/case.py"}, {"linenr": 25, "function": "test_list_literals", "line": "self.assertEqual([1, __], nums)", "filename": "/Users/ops/Projects/PyKata/test/test_lists.py"}]}, "result": "error", "name": "test_list_literals"}, {"error": {"message": "NameError: global name '__' is not defined", "traceback": [{"linenr": 329, "function": "run", "line": "testMethod()", "filename": "/usr/local/Cellar/python/2.7.12/Frameworks/Python.framework/Versions/2.7/lib/python2.7/unittest/case.py"}, {"linenr": 57, "function": "test_lists_and_ranges", "line": "self.assertEqual(__, range(5))", "filename": "/Users/ops/Projects/PyKata/test/test_lists.py"}]}, "result": "error", "name": "test_lists_and_ranges"}, {"error": {"message": "NameError: global name '__' is not defined", "traceback": [{"linenr": 329, "function": "run", "line": "testMethod()", "filename": "/usr/local/Cellar/python/2.7.12/Frameworks/Python.framework/Versions/2.7/lib/python2.7/unittest/case.py"}, {"linenr": 79, "function": "test_popping_lists", "line": "self.assertEqual(__, stack)", "filename": "/Users/ops/Projects/PyKata/test/test_lists.py"}]}, "result": "error", "name": "test_popping_lists"}, {"error": {"message": "NameError: global name '__' is not defined", "traceback": [{"linenr": 329, "function": "run", "line": "testMethod()", "filename": "/usr/local/Cellar/python/2.7.12/Frameworks/Python.framework/Versions/2.7/lib/python2.7/unittest/case.py"}, {"linenr": 61, "function": "test_ranges_with_steps", "line": "self.assertEqual(__, range(5, 3, -1))", "filename": "/Users/ops/Projects/PyKata/test/test_lists.py"}]}, "result": "error", "name": "test_ranges_with_steps"}, {"error": {"message": "NameError: global name '__' is not defined", "traceback": [{"linenr": 329, "function": "run", "line": "testMethod()", "filename": "/usr/local/Cellar/python/2.7.12/Frameworks/Python.framework/Versions/2.7/lib/python2.7/unittest/case.py"}, {"linenr": 41, "function": "test_slicing_lists", "line": "self.assertEqual(__, noms[0:1])", "filename": "/Users/ops/Projects/PyKata/test/test_lists.py"}]}, "result": "error", "name": "test_slicing_lists"}, {"error": {"message": "NameError: global name '__' is not defined", "traceback": [{"linenr": 329, "function": "run", "line": "testMethod()", "filename": "/usr/local/Cellar/python/2.7.12/Frameworks/Python.framework/Versions/2.7/lib/python2.7/unittest/case.py"}, {"linenr": 52, "function": "test_slicing_to_the_edge", "line": "self.assertEqual(__, noms[2:])", "filename": "/Users/ops/Projects/PyKata/test/test_lists.py"}]}, "result": "error", "name": "test_slicing_to_the_edge"}, {"error": {"message": "NameError: global name '__' is not defined", "traceback": [{"linenr": 329, "function": "run", "line": "testMethod()", "filename": "/usr/local/Cellar/python/2.7.12/Frameworks/Python.framework/Versions/2.7/lib/python2.7/unittest/case.py"}, {"linenr": 103, "function": "test_use_deques_for_making_queues", "line": "self.assertEqual(__, list(queue))", "filename": "/Users/ops/Projects/PyKata/test/test_lists.py"}]}, "result": "error", "name": "test_use_deques_for_making_queues"}], "nr_error": 10, "nr_success": 0, "name": "test.test_lists.AboutLists", "nr_failed": 0}, {"testcases": [{"error": {"message": "NameError: global name '__' is not defined", "traceback": [{"linenr": 329, "function": "run", "line": "testMethod()", "filename": "/usr/local/Cellar/python/2.7.12/Frameworks/Python.framework/Versions/2.7/lib/python2.7/unittest/case.py"}, {"linenr": 36, "function": "test_bound_methods_have_different_attributes", "line": "self.assertEqual(__, len(dir(obj.method)))", "filename": "/Users/ops/Projects/PyKata/test/test_method_bindings.py"}]}, "result": "error", "name": "test_bound_methods_have_different_attributes"}, {"error": {"message": "NameError: global name '__' is not defined", "traceback": [{"linenr": 329, "function": "run", "line": "testMethod()", "filename": "/usr/local/Cellar/python/2.7.12/Frameworks/Python.framework/Versions/2.7/lib/python2.7/unittest/case.py"}, {"linenr": 56, "function": "test_functions_can_have_inner_functions", "line": "self.assertEqual(__, function2.get_fruit())", "filename": "/Users/ops/Projects/PyKata/test/test_method_bindings.py"}]}, "result": "error", "name": "test_functions_can_have_inner_functions"}, {"error": {"message": "NameError: global name '__' is not defined", "traceback": [{"linenr": 329, "function": "run", "line": "testMethod()", "filename": "/usr/local/Cellar/python/2.7.12/Frameworks/Python.framework/Versions/2.7/lib/python2.7/unittest/case.py"}, {"linenr": 31, "function": "test_functions_have_attributes", "line": "self.assertEqual(__, len(dir(function)))", "filename": "/Users/ops/Projects/PyKata/test/test_method_bindings.py"}]}, "result": "error", "name": "test_functions_have_attributes"}, {"error": {"message": "NameError: global name '__' is not defined", "traceback": [{"linenr": 329, "function": "run", "line": "testMethod()", "filename": "/usr/local/Cellar/python/2.7.12/Frameworks/Python.framework/Versions/2.7/lib/python2.7/unittest/case.py"}, {"linenr": 80, "function": "test_get_descriptor_resolves_attribute_binding", "line": "self.assertEqual(__, bound_obj.__class__.__name__)", "filename": "/Users/ops/Projects/PyKata/test/test_method_bindings.py"}]}, "result": "error", "name": "test_get_descriptor_resolves_attribute_binding"}, {"error": {"message": "AttributeError: 'AboutMethodBindings' object has no attribute 'assertMatch'", "traceback": [{"linenr": 329, "function": "run", "line": "testMethod()", "filename": "/usr/local/Cellar/python/2.7.12/Frameworks/Python.framework/Versions/2.7/lib/python2.7/unittest/case.py"}, {"linenr": 63, "function": "test_inner_functions_are_unbound", "line": "self.assertMatch(__, ex[0])", "filename": "/Users/ops/Projects/PyKata/test/test_method_bindings.py"}]}, "result": "error", "name": "test_inner_functions_are_unbound"}, {"error": {"message": "NameError: global name '__' is not defined", "traceback": [{"linenr": 329, "function": "run", "line": "testMethod()", "filename": "/usr/local/Cellar/python/2.7.12/Frameworks/Python.framework/Versions/2.7/lib/python2.7/unittest/case.py"}, {"linenr": 27, "function": "test_methods_are_also_bound_to_a_function", "line": "self.assertEqual(__, obj.method())", "filename": "/Users/ops/Projects/PyKata/test/test_method_bindings.py"}]}, "result": "error", "name": "test_methods_are_also_bound_to_a_function"}, {"error": {"message": "NameError: global name '__' is not defined", "traceback": [{"linenr": 329, "function": "run", "line": "testMethod()", "filename": "/usr/local/Cellar/python/2.7.12/Frameworks/Python.framework/Versions/2.7/lib/python2.7/unittest/case.py"}, {"linenr": 23, "function": "test_methods_are_bound_to_an_object", "line": "self.assertEqual(__, obj.method.im_self == obj)", "filename": "/Users/ops/Projects/PyKata/test/test_method_bindings.py"}]}, "result": "error", "name": "test_methods_are_bound_to_an_object"}, {"error": {"message": "NameError: global name '__' is not defined", "traceback": [{"linenr": 329, "function": "run", "line": "testMethod()", "filename": "/usr/local/Cellar/python/2.7.12/Frameworks/Python.framework/Versions/2.7/lib/python2.7/unittest/case.py"}, {"linenr": 98, "function": "test_set_descriptor_changes_behavior_of_attribute_assignment", "line": "self.assertEqual(__, self.color.choice)", "filename": "/Users/ops/Projects/PyKata/test/test_method_bindings.py"}]}, "result": "error", "name": "test_set_descriptor_changes_behavior_of_attribute_assignment"}, {"error": {"message": "AttributeError: 'AboutMethodBindings' object has no attribute 'assertMatch'", "traceback": [{"linenr": 329, "function": "run", "line": "testMethod()", "filename": "/usr/local/Cellar/python/2.7.12/Frameworks/Python.framework/Versions/2.7/lib/python2.7/unittest/case.py"}, {"linenr": 47, "function": "test_setting_attributes_on_a_bound_method_directly", "line": "self.assertMatch(__, ex[0])", "filename": "/Users/ops/Projects/PyKata/test/test_method_bindings.py"}]}, "result": "error", "name": "test_setting_attributes_on_a_bound_method_directly"}, {"error": {"message": "NameError: global name '__' is not defined", "traceback": [{"linenr": 329, "function": "run", "line": "testMethod()", "filename": "/usr/local/Cellar/python/2.7.12/Frameworks/Python.framework/Versions/2.7/lib/python2.7/unittest/case.py"}, {"linenr": 40, "function": "test_setting_attributes_on_an_unbound_function", "line": "self.assertEqual(__, function.cherries)", "filename": "/Users/ops/Projects/PyKata/test/test_method_bindings.py"}]}, "result": "error", "name": "test_setting_attributes_on_an_unbound_function"}, {"error": {"message": "NameError: global name '__' is not defined", "traceback": [{"linenr": 329, "function": "run", "line": "testMethod()", "filename": "/usr/local/Cellar/python/2.7.12/Frameworks/Python.framework/Versions/2.7/lib/python2.7/unittest/case.py"}, {"linenr": 52, "function": "test_setting_attributes_on_methods_by_accessing_the_inner_function", "line": "self.assertEqual(__, obj.method.cherries)", "filename": "/Users/ops/Projects/PyKata/test/test_method_bindings.py"}]}, "result": "error", "name": "test_setting_attributes_on_methods_by_accessing_the_inner_function"}], "nr_error": 11, "nr_success": 0, "name": "test.test_method_bindings.AboutMethodBindings", "nr_failed": 0}, {"testcases": [{"error": {"message": "NameError: global name '__' is not defined", "traceback": [{"linenr": 329, "function": "run", "line": "testMethod()", "filename": "/usr/local/Cellar/python/2.7.12/Frameworks/Python.framework/Versions/2.7/lib/python2.7/unittest/case.py"}, {"linenr": 17, "function": "test_calling_a_global_function", "line": "self.assertEqual(__, my_global_function(2, 3))", "filename": "/Users/ops/Projects/PyKata/test/test_methods.py"}]}, "result": "error", "name": "test_calling_a_global_function"}, {"error": {"message": "NameError: global name '__' is not defined", "traceback": [{"linenr": 329, "function": "run", "line": "testMethod()", "filename": "/usr/local/Cellar/python/2.7.12/Frameworks/Python.framework/Versions/2.7/lib/python2.7/unittest/case.py"}, {"linenr": 27, "function": "test_calling_functions_with_wrong_number_of_arguments", "line": "self.assertEqual(__, exception.__class__.__name__)", "filename": "/Users/ops/Projects/PyKata/test/test_methods.py"}]}, "result": "error", "name": "test_calling_functions_with_wrong_number_of_arguments"}, {"error": {"message": "NameError: global name '__' is not defined", "traceback": [{"linenr": 329, "function": "run", "line": "testMethod()", "filename": "/usr/local/Cellar/python/2.7.12/Frameworks/Python.framework/Versions/2.7/lib/python2.7/unittest/case.py"}, {"linenr": 147, "function": "test_calling_methods_in_other_objects", "line": "self.assertEqual(__, rover.name())", "filename": "/Users/ops/Projects/PyKata/test/test_methods.py"}]}, "result": "error", "name": "test_calling_methods_in_other_objects"}, {"error": {"message": "NameError: global name '__' is not defined", "traceback": [{"linenr": 329, "function": "run", "line": "testMethod()", "filename": "/usr/local/Cellar/python/2.7.12/Frameworks/Python.framework/Versions/2.7/lib/python2.7/unittest/case.py"}, {"linenr": 83, "function": "test_calling_methods_in_same_class_with_explicit_receiver", "line": "self.assertEqual(__, self.function_with_the_same_name(3, 4))", "filename": "/Users/ops/Projects/PyKata/test/test_methods.py"}]}, "result": "error", "name": "test_calling_methods_in_same_class_with_explicit_receiver"}, {"error": {"message": "NameError: global name '__' is not defined", "traceback": [{"linenr": 329, "function": "run", "line": "testMethod()", "filename": "/usr/local/Cellar/python/2.7.12/Frameworks/Python.framework/Versions/2.7/lib/python2.7/unittest/case.py"}, {"linenr": 55, "function": "test_calling_with_default_values", "line": "self.assertEqual(__, self.method_with_defaults(1))", "filename": "/Users/ops/Projects/PyKata/test/test_methods.py"}]}, "result": "error", "name": "test_calling_with_default_values"}, {"error": {"message": "NameError: global name '__' is not defined", "traceback": [{"linenr": 329, "function": "run", "line": "testMethod()", "filename": "/usr/local/Cellar/python/2.7.12/Frameworks/Python.framework/Versions/2.7/lib/python2.7/unittest/case.py"}, {"linenr": 64, "function": "test_calling_with_variable_arguments", "line": "self.assertEqual(__, self.method_with_var_args())", "filename": "/Users/ops/Projects/PyKata/test/test_methods.py"}]}, "result": "error", "name": "test_calling_with_variable_arguments"}, {"error": {"message": "NameError: global name '__' is not defined", "traceback": [{"linenr": 329, "function": "run", "line": "testMethod()", "filename": "/usr/local/Cellar/python/2.7.12/Frameworks/Python.framework/Versions/2.7/lib/python2.7/unittest/case.py"}, {"linenr": 163, "function": "test_double_underscore_attribute_prefixes_cause_name_mangling", "line": "self.assertEqual(__, ex.__class__.__name__)", "filename": "/Users/ops/Projects/PyKata/test/test_methods.py"}]}, "result": "error", "name": "test_double_underscore_attribute_prefixes_cause_name_mangling"}, {"error": {"message": "NameError: global name '__' is not defined", "traceback": [{"linenr": 329, "function": "run", "line": "testMethod()", "filename": "/usr/local/Cellar/python/2.7.12/Frameworks/Python.framework/Versions/2.7/lib/python2.7/unittest/case.py"}, {"linenr": 77, "function": "test_functions_without_self_arg_are_global_functions", "line": "self.assertEqual(__, function_with_the_same_name(3, 4))", "filename": "/Users/ops/Projects/PyKata/test/test_methods.py"}]}, "result": "error", "name": "test_functions_without_self_arg_are_global_functions"}, {"error": {"message": "NameError: global name '__' is not defined", "traceback": [{"linenr": 329, "function": "run", "line": "testMethod()", "filename": "/usr/local/Cellar/python/2.7.12/Frameworks/Python.framework/Versions/2.7/lib/python2.7/unittest/case.py"}, {"linenr": 107, "function": "test_methods_that_do_nothing_need_to_use_pass_as_a_filler", "line": "self.assertEqual(__, self.empty_method())", "filename": "/Users/ops/Projects/PyKata/test/test_methods.py"}]}, "result": "error", "name": "test_methods_that_do_nothing_need_to_use_pass_as_a_filler"}, {"error": {"message": "NameError: global name '__' is not defined", "traceback": [{"linenr": 329, "function": "run", "line": "testMethod()", "filename": "/usr/local/Cellar/python/2.7.12/Frameworks/Python.framework/Versions/2.7/lib/python2.7/unittest/case.py"}, {"linenr": 121, "function": "test_no_indentation_required_for_one_line_statement_bodies", "line": "self.assertEqual(__, self.one_line_method())", "filename": "/Users/ops/Projects/PyKata/test/test_methods.py"}]}, "result": "error", "name": "test_no_indentation_required_for_one_line_statement_bodies"}, {"error": {"message": "NameError: global name '____' is not defined", "traceback": [{"linenr": 329, "function": "run", "line": "testMethod()", "filename": "/usr/local/Cellar/python/2.7.12/Frameworks/Python.framework/Versions/2.7/lib/python2.7/unittest/case.py"}, {"linenr": 114, "function": "test_pass_does_nothing_at_all", "line": "self.assertEqual(____, \"Still got to this line\" != None)", "filename": "/Users/ops/Projects/PyKata/test/test_methods.py"}]}, "result": "error", "name": "test_pass_does_nothing_at_all"}, {"error": {"message": "NameError: global name '__' is not defined", "traceback": [{"linenr": 329, "function": "run", "line": "testMethod()", "filename": "/usr/local/Cellar/python/2.7.12/Frameworks/Python.framework/Versions/2.7/lib/python2.7/unittest/case.py"}, {"linenr": 153, "function": "test_private_access_is_implied_but_not_enforced", "line": "self.assertEqual(__, rover._tail())", "filename": "/Users/ops/Projects/PyKata/test/test_methods.py"}]}, "result": "error", "name": "test_private_access_is_implied_but_not_enforced"}, {"error": {"message": "NameError: global name '__' is not defined", "traceback": [{"linenr": 329, "function": "run", "line": "testMethod()", "filename": "/usr/local/Cellar/python/2.7.12/Frameworks/Python.framework/Versions/2.7/lib/python2.7/unittest/case.py"}, {"linenr": 96, "function": "test_that_old_methods_are_hidden_by_redefinitions", "line": "self.assertEqual(__, self.another_method_with_the_same_name())", "filename": "/Users/ops/Projects/PyKata/test/test_methods.py"}]}, "result": "error", "name": "test_that_old_methods_are_hidden_by_redefinitions"}, {"error": {"message": "NameError: global name '__' is not defined", "traceback": [{"linenr": 329, "function": "run", "line": "testMethod()", "filename": "/usr/local/Cellar/python/2.7.12/Frameworks/Python.framework/Versions/2.7/lib/python2.7/unittest/case.py"}, {"linenr": 99, "function": "test_that_overlapped_method_is_still_there", "line": "self.assertEqual(__, self.link_to_overlapped_method())", "filename": "/Users/ops/Projects/PyKata/test/test_methods.py"}]}, "result": "error", "name": "test_that_overlapped_method_is_still_there"}, {"error": {"message": "AttributeError: 'AboutMethods' object has no attribute 'assertMatch'", "traceback": [{"linenr": 329, "function": "run", "line": "testMethod()", "filename": "/usr/local/Cellar/python/2.7.12/Frameworks/Python.framework/Versions/2.7/lib/python2.7/unittest/case.py"}, {"linenr": 130, "function": "test_the_documentation_can_be_viewed_with_the_doc_method", "line": "self.assertMatch(__, self.method_with_documentation.__doc__)", "filename": "/Users/ops/Projects/PyKata/test/test_methods.py"}]}, "result": "error", "name": "test_the_documentation_can_be_viewed_with_the_doc_method"}, {"error": {"message": "NameError: global name '__' is not defined", "traceback": [{"linenr": 329, "function": "run", "line": "testMethod()", "filename": "/usr/local/Cellar/python/2.7.12/Frameworks/Python.framework/Versions/2.7/lib/python2.7/unittest/case.py"}, {"linenr": 45, "function": "test_which_does_not_return_anything", "line": "self.assertEqual(__, self.pointless_method(1, 2))", "filename": "/Users/ops/Projects/PyKata/test/test_methods.py"}]}, "result": "error", "name": "test_which_does_not_return_anything"}], "nr_error": 16, "nr_success": 0, "name": "test.test_methods.AboutMethods", "nr_failed": 0}, {"testcases": [{"error": {"message": "NameError: global name '__' is not defined", "traceback": [{"linenr": 329, "function": "run", "line": "testMethod()", "filename": "/usr/local/Cellar/python/2.7.12/Frameworks/Python.framework/Versions/2.7/lib/python2.7/unittest/case.py"}, {"linenr": 71, "function": "test_a_module_can_limit_wildcard_imports", "line": "self.assertEqual(__, goat.name)", "filename": "/Users/ops/Projects/PyKata/test/test_modules.py"}]}, "result": "error", "name": "test_a_module_can_limit_wildcard_imports"}, {"error": {"message": "NameError: global name '__' is not defined", "traceback": [{"linenr": 329, "function": "run", "line": "testMethod()", "filename": "/usr/local/Cellar/python/2.7.12/Frameworks/Python.framework/Versions/2.7/lib/python2.7/unittest/case.py"}, {"linenr": 46, "function": "test_importing_all_module_attributes_at_once", "line": "self.assertEqual(__, goose.name)", "filename": "/Users/ops/Projects/PyKata/test/test_modules.py"}]}, "result": "error", "name": "test_importing_all_module_attributes_at_once"}, {"error": {"message": "NameError: global name '__' is not defined", "traceback": [{"linenr": 329, "function": "run", "line": "testMethod()", "filename": "/usr/local/Cellar/python/2.7.12/Frameworks/Python.framework/Versions/2.7/lib/python2.7/unittest/case.py"}, {"linenr": 26, "function": "test_importing_attributes_from_classes_using_from_keyword", "line": "self.assertEqual(__, duck.name)", "filename": "/Users/ops/Projects/PyKata/test/test_modules.py"}]}, "result": "error", "name": "test_importing_attributes_from_classes_using_from_keyword"}, {"error": {"message": "NameError: global name '__' is not defined", "traceback": [{"linenr": 329, "function": "run", "line": "testMethod()", "filename": "/usr/local/Cellar/python/2.7.12/Frameworks/Python.framework/Versions/2.7/lib/python2.7/unittest/case.py"}, {"linenr": 20, "function": "test_importing_other_python_scripts_as_modules", "line": "self.assertEqual(__, duck.name)", "filename": "/Users/ops/Projects/PyKata/test/test_modules.py"}]}, "result": "error", "name": "test_importing_other_python_scripts_as_modules"}, {"error": {"message": "AttributeError: 'AboutModules' object has no attribute 'assertMatch'", "traceback": [{"linenr": 329, "function": "run", "line": "testMethod()", "filename": "/usr/local/Cellar/python/2.7.12/Frameworks/Python.framework/Versions/2.7/lib/python2.7/unittest/case.py"}, {"linenr": 53, "function": "test_modules_hide_attributes_prefixed_by_underscores", "line": "self.assertMatch(__, ex[0])", "filename": "/Users/ops/Projects/PyKata/test/test_modules.py"}]}, "result": "error", "name": "test_modules_hide_attributes_prefixed_by_underscores"}, {"error": {"message": "NameError: global name '__' is not defined", "traceback": [{"linenr": 329, "function": "run", "line": "testMethod()", "filename": "/usr/local/Cellar/python/2.7.12/Frameworks/Python.framework/Versions/2.7/lib/python2.7/unittest/case.py"}, {"linenr": 59, "function": "test_private_attributes_are_still_accessible_in_modules", "line": "self.assertEqual(__, duck._password)", "filename": "/Users/ops/Projects/PyKata/test/test_modules.py"}]}, "result": "error", "name": "test_private_attributes_are_still_accessible_in_modules"}, {"error": {"message": "NameError: global name '__' is not defined", "traceback": [{"linenr": 329, "function": "run", "line": "testMethod()", "filename": "/usr/local/Cellar/python/2.7.12/Frameworks/Python.framework/Versions/2.7/lib/python2.7/unittest/case.py"}, {"linenr": 33, "function": "test_we_can_import_multiple_items_at_once", "line": "self.assertEqual(__, jims_dog.identify())", "filename": "/Users/ops/Projects/PyKata/test/test_modules.py"}]}, "result": "error", "name": "test_we_can_import_multiple_items_at_once"}], "nr_error": 7, "nr_success": 0, "name": "test.test_modules.AboutModules", "nr_failed": 0}, {"testcases": [{"error": {"message": "NameError: global name '__' is not defined", "traceback": [{"linenr": 329, "function": "run", "line": "testMethod()", "filename": "/usr/local/Cellar/python/2.7.12/Frameworks/Python.framework/Versions/2.7/lib/python2.7/unittest/case.py"}, {"linenr": 30, "function": "test_after_patching_dogs_can_both_wag_and_bark", "line": "self.assertEqual(__, fido.wag())", "filename": "/Users/ops/Projects/PyKata/test/test_monkey_patching.py"}]}, "result": "error", "name": "test_after_patching_dogs_can_both_wag_and_bark"}, {"error": {"message": "NameError: global name '__' is not defined", "traceback": [{"linenr": 329, "function": "run", "line": "testMethod()", "filename": "/usr/local/Cellar/python/2.7.12/Frameworks/Python.framework/Versions/2.7/lib/python2.7/unittest/case.py"}, {"linenr": 18, "function": "test_as_defined_dogs_do_bark", "line": "self.assertEqual(__, fido.bark())", "filename": "/Users/ops/Projects/PyKata/test/test_monkey_patching.py"}]}, "result": "error", "name": "test_as_defined_dogs_do_bark"}, {"error": {"message": "AttributeError: 'AboutMonkeyPatching' object has no attribute 'assertMatch'", "traceback": [{"linenr": 329, "function": "run", "line": "testMethod()", "filename": "/usr/local/Cellar/python/2.7.12/Frameworks/Python.framework/Versions/2.7/lib/python2.7/unittest/case.py"}, {"linenr": 39, "function": "test_most_built_in_classes_cannot_be_monkey_patched", "line": "self.assertMatch(__, ex[0])", "filename": "/Users/ops/Projects/PyKata/test/test_monkey_patching.py"}]}, "result": "error", "name": "test_most_built_in_classes_cannot_be_monkey_patched"}, {"error": {"message": "NameError: global name '____' is not defined", "traceback": [{"linenr": 329, "function": "run", "line": "testMethod()", "filename": "/usr/local/Cellar/python/2.7.12/Frameworks/Python.framework/Versions/2.7/lib/python2.7/unittest/case.py"}, {"linenr": 49, "function": "test_subclasses_of_built_in_classes_can_be_be_monkey_patched", "line": "self.assertEqual(____, self.MyInt(1).is_even())", "filename": "/Users/ops/Projects/PyKata/test/test_monkey_patching.py"}]}, "result": "error", "name": "test_subclasses_of_built_in_classes_can_be_be_monkey_patched"}], "nr_error": 4, "nr_success": 0, "name": "test.test_monkey_patching.AboutMonkeyPatching", "nr_failed": 0}, {"testcases": [{"error": {"message": "NameError: global name '____' is not defined", "traceback": [{"linenr": 329, "function": "run", "line": "testMethod()", "filename": "/usr/local/Cellar/python/2.7.12/Frameworks/Python.framework/Versions/2.7/lib/python2.7/unittest/case.py"}, {"linenr": 99, "function": "test_base_class_methods_are_also_available_in_the_object", "line": "self.assertEqual(____, jeff.can_climb_walls())", "filename": "/Users/ops/Projects/PyKata/test/test_multiple_inheritance.py"}]}, "result": "error", "name": "test_base_class_methods_are_also_available_in_the_object"}, {"error": {"message": "NameError: global name '__' is not defined", "traceback": [{"linenr": 329, "function": "run", "line": "testMethod()", "filename": "/usr/local/Cellar/python/2.7.12/Frameworks/Python.framework/Versions/2.7/lib/python2.7/unittest/case.py"}, {"linenr": 103, "function": "test_base_class_methods_can_affect_instance_variables_in_the_object", "line": "self.assertEqual(__, jeff.name)", "filename": "/Users/ops/Projects/PyKata/test/test_multiple_inheritance.py"}]}, "result": "error", "name": "test_base_class_methods_can_affect_instance_variables_in_the_object"}, {"error": {"message": "AttributeError: 'AboutMultipleInheritance' object has no attribute 'assertMatch'", "traceback": [{"linenr": 329, "function": "run", "line": "testMethod()", "filename": "/usr/local/Cellar/python/2.7.12/Frameworks/Python.framework/Versions/2.7/lib/python2.7/unittest/case.py"}, {"linenr": 130, "function": "test_confirm_the_mro_controls_the_calling_order", "line": "self.assertMatch('Spiderpig', jeff.here())", "filename": "/Users/ops/Projects/PyKata/test/test_multiple_inheritance.py"}]}, "result": "error", "name": "test_confirm_the_mro_controls_the_calling_order"}, {"error": {"message": "NameError: global name '__' is not defined", "traceback": [{"linenr": 329, "function": "run", "line": "testMethod()", "filename": "/usr/local/Cellar/python/2.7.12/Frameworks/Python.framework/Versions/2.7/lib/python2.7/unittest/case.py"}, {"linenr": 110, "function": "test_left_hand_side_inheritance_tends_to_be_higher_priority", "line": "self.assertEqual(__, jeff.color())", "filename": "/Users/ops/Projects/PyKata/test/test_multiple_inheritance.py"}]}, "result": "error", "name": "test_left_hand_side_inheritance_tends_to_be_higher_priority"}, {"error": {"message": "AttributeError: 'AboutMultipleInheritance' object has no attribute 'assertMatch'", "traceback": [{"linenr": 329, "function": "run", "line": "testMethod()", "filename": "/usr/local/Cellar/python/2.7.12/Frameworks/Python.framework/Versions/2.7/lib/python2.7/unittest/case.py"}, {"linenr": 91, "function": "test_normal_methods_are_available_in_the_object", "line": "self.assertMatch(__, jeff.speak())", "filename": "/Users/ops/Projects/PyKata/test/test_multiple_inheritance.py"}]}, "result": "error", "name": "test_normal_methods_are_available_in_the_object"}, {"error": {"message": "NameError: global name '__' is not defined", "traceback": [{"linenr": 329, "function": "run", "line": "testMethod()", "filename": "/usr/local/Cellar/python/2.7.12/Frameworks/Python.framework/Versions/2.7/lib/python2.7/unittest/case.py"}, {"linenr": 114, "function": "test_super_class_methods_are_higher_priority_than_super_super_classes", "line": "self.assertEqual(__, jeff.legs())", "filename": "/Users/ops/Projects/PyKata/test/test_multiple_inheritance.py"}]}, "result": "error", "name": "test_super_class_methods_are_higher_priority_than_super_super_classes"}, {"error": {"message": "NameError: global name '__' is not defined", "traceback": [{"linenr": 329, "function": "run", "line": "testMethod()", "filename": "/usr/local/Cellar/python/2.7.12/Frameworks/Python.framework/Versions/2.7/lib/python2.7/unittest/case.py"}, {"linenr": 123, "function": "test_we_can_inspect_the_method_resolution_order", "line": "self.assertEqual(__, mro[2].__name__)", "filename": "/Users/ops/Projects/PyKata/test/test_multiple_inheritance.py"}]}, "result": "error", "name": "test_we_can_inspect_the_method_resolution_order"}], "nr_error": 7, "nr_success": 0, "name": "test.test_multiple_inheritance.AboutMultipleInheritance", "nr_failed": 0}, {"testcases": [{"error": {"message": "NameError: global name '__' is not defined", "traceback": [{"linenr": 329, "function": "run", "line": "testMethod()", "filename": "/usr/local/Cellar/python/2.7.12/Frameworks/Python.framework/Versions/2.7/lib/python2.7/unittest/case.py"}, {"linenr": 58, "function": "test_in_old_style_instances_class_is_different_to_type", "line": "self.assertEqual(__, old_style.__class__.__name__)", "filename": "/Users/ops/Projects/PyKata/test/test_new_style_classes.py"}]}, "result": "error", "name": "test_in_old_style_instances_class_is_different_to_type"}, {"error": {"message": "NameError: global name '__' is not defined", "traceback": [{"linenr": 329, "function": "run", "line": "testMethod()", "filename": "/usr/local/Cellar/python/2.7.12/Frameworks/Python.framework/Versions/2.7/lib/python2.7/unittest/case.py"}, {"linenr": 25, "function": "test_new_style_classes_have_more_attributes", "line": "self.assertEqual(__, len(dir(self.OldStyleClass)))", "filename": "/Users/ops/Projects/PyKata/test/test_new_style_classes.py"}]}, "result": "error", "name": "test_new_style_classes_have_more_attributes"}, {"error": {"message": "NameError: global name '__' is not defined", "traceback": [{"linenr": 329, "function": "run", "line": "testMethod()", "filename": "/usr/local/Cellar/python/2.7.12/Frameworks/Python.framework/Versions/2.7/lib/python2.7/unittest/case.py"}, {"linenr": 49, "function": "test_new_style_classes_have_same_class_as_type", "line": "self.assertEqual(__, self.NewStyleClass.__class__)", "filename": "/Users/ops/Projects/PyKata/test/test_new_style_classes.py"}]}, "result": "error", "name": "test_new_style_classes_have_same_class_as_type"}, {"error": {"message": "NameError: global name '____' is not defined", "traceback": [{"linenr": 329, "function": "run", "line": "testMethod()", "filename": "/usr/local/Cellar/python/2.7.12/Frameworks/Python.framework/Versions/2.7/lib/python2.7/unittest/case.py"}, {"linenr": 21, "function": "test_new_style_classes_inherit_from_object_base_class", "line": "self.assertEqual(____, issubclass(self.NewStyleClass, object))", "filename": "/Users/ops/Projects/PyKata/test/test_new_style_classes.py"}]}, "result": "error", "name": "test_new_style_classes_inherit_from_object_base_class"}, {"error": {"message": "NameError: global name '__' is not defined", "traceback": [{"linenr": 329, "function": "run", "line": "testMethod()", "filename": "/usr/local/Cellar/python/2.7.12/Frameworks/Python.framework/Versions/2.7/lib/python2.7/unittest/case.py"}, {"linenr": 63, "function": "test_new_style_instances_have_same_class_as_type", "line": "self.assertEqual(__, new_style.__class__.__name__)", "filename": "/Users/ops/Projects/PyKata/test/test_new_style_classes.py"}]}, "result": "error", "name": "test_new_style_instances_have_same_class_as_type"}, {"error": {"message": "NameError: global name '__' is not defined", "traceback": [{"linenr": 329, "function": "run", "line": "testMethod()", "filename": "/usr/local/Cellar/python/2.7.12/Frameworks/Python.framework/Versions/2.7/lib/python2.7/unittest/case.py"}, {"linenr": 37, "function": "test_old_style_classes_have_type_but_no_class_attribute", "line": "self.assertEqual(__, type(self.OldStyleClass).__name__)", "filename": "/Users/ops/Projects/PyKata/test/test_new_style_classes.py"}]}, "result": "error", "name": "test_old_style_classes_have_type_but_no_class_attribute"}], "nr_error": 6, "nr_success": 0, "name": "test.test_new_style_classes.AboutNewStyleClasses", "nr_failed": 0}, {"testcases": [{"result": "success", "name": "test_none_is_an_object"}, {"result": "success", "name": "test_none_is_distinct"}, {"result": "success", "name": "test_none_is_universal"}, {"result": "success", "name": "test_what_exception_do_you_get_when_calling_nonexistent_methods"}], "nr_error": 0, "nr_success": 4, "name": "test.test_none.AboutNone", "nr_failed": 0}, {"testcases": [{"error": {"message": "ImportError: No module named koans.a_package_folder.a_module", "traceback": [{"linenr": 329, "function": "run", "line": "testMethod()", "filename": "/usr/local/Cellar/python/2.7.12/Frameworks/Python.framework/Versions/2.7/lib/python2.7/unittest/case.py"}, {"linenr": 66, "function": "test_import_a_module_in_a_subfolder_using_an_absolute_path", "line": "from koans.a_package_folder.a_module import Duck", "filename": "/Users/ops/Projects/PyKata/test/test_packages.py"}]}, "result": "error", "name": "test_import_a_module_in_a_subfolder_using_an_absolute_path"}, {"error": {"message": "NameError: global name '__' is not defined", "traceback": [{"linenr": 329, "function": "run", "line": "testMethod()", "filename": "/usr/local/Cellar/python/2.7.12/Frameworks/Python.framework/Versions/2.7/lib/python2.7/unittest/case.py"}, {"linenr": 39, "function": "test_subfolders_become_modules_if_they_have_an_init_module", "line": "self.assertEqual(__, an_attribute)", "filename": "/Users/ops/Projects/PyKata/test/test_packages.py"}]}, "result": "error", "name": "test_subfolders_become_modules_if_they_have_an_init_module"}, {"error": {"message": "NameError: global name '__' is not defined", "traceback": [{"linenr": 329, "function": "run", "line": "testMethod()", "filename": "/usr/local/Cellar/python/2.7.12/Frameworks/Python.framework/Versions/2.7/lib/python2.7/unittest/case.py"}, {"linenr": 33, "function": "test_subfolders_can_form_part_of_a_module_package", "line": "self.assertEqual(__, duck.name)", "filename": "/Users/ops/Projects/PyKata/test/test_packages.py"}]}, "result": "error", "name": "test_subfolders_can_form_part_of_a_module_package"}, {"error": {"message": "AttributeError: 'AboutPackages' object has no attribute 'assertMatch'", "traceback": [{"linenr": 329, "function": "run", "line": "testMethod()", "filename": "/usr/local/Cellar/python/2.7.12/Frameworks/Python.framework/Versions/2.7/lib/python2.7/unittest/case.py"}, {"linenr": 46, "function": "test_subfolders_without_an_init_module_are_not_part_of_the_package", "line": "self.assertMatch(__, ex[0])", "filename": "/Users/ops/Projects/PyKata/test/test_packages.py"}]}, "result": "error", "name": "test_subfolders_without_an_init_module_are_not_part_of_the_package"}, {"error": {"message": "ImportError: No module named contemplate_koans", "traceback": [{"linenr": 329, "function": "run", "line": "testMethod()", "filename": "/usr/local/Cellar/python/2.7.12/Frameworks/Python.framework/Versions/2.7/lib/python2.7/unittest/case.py"}, {"linenr": 52, "function": "test_use_absolute_imports_to_import_upper_level_modules", "line": "import contemplate_koans", "filename": "/Users/ops/Projects/PyKata/test/test_packages.py"}]}, "result": "error", "name": "test_use_absolute_imports_to_import_upper_level_modules"}], "nr_error": 5, "nr_success": 0, "name": "test.test_packages.AboutPackages", "nr_failed": 0}, {"testcases": [{"error": {"message": "AttributeError: 'Proxy' object has no attribute 'upper'", "traceback": [{"linenr": 329, "function": "run", "line": "testMethod()", "filename": "/usr/local/Cellar/python/2.7.12/Frameworks/Python.framework/Versions/2.7/lib/python2.7/unittest/case.py"}, {"linenr": 92, "function": "test_proxy_can_record_more_than_just_tv_objects", "line": "result = proxy.upper()", "filename": "/Users/ops/Projects/PyKata/test/test_proxy_object_project.py"}]}, "result": "error", "name": "test_proxy_can_record_more_than_just_tv_objects"}, {"error": {"message": "AttributeError: 'Proxy' object has no attribute 'power'", "traceback": [{"linenr": 329, "function": "run", "line": "testMethod()", "filename": "/usr/local/Cellar/python/2.7.12/Frameworks/Python.framework/Versions/2.7/lib/python2.7/unittest/case.py"}, {"linenr": 81, "function": "test_proxy_counts_method_calls", "line": "tv.power()", "filename": "/Users/ops/Projects/PyKata/test/test_proxy_object_project.py"}]}, "result": "error", "name": "test_proxy_counts_method_calls"}, {"result": "success", "name": "test_proxy_handles_invalid_messages"}, {"result": "success", "name": "test_proxy_method_returns_wrapped_object"}, {"error": {"message": "AttributeError: 'Proxy' object has no attribute 'power'", "traceback": [{"linenr": 329, "function": "run", "line": "testMethod()", "filename": "/usr/local/Cellar/python/2.7.12/Frameworks/Python.framework/Versions/2.7/lib/python2.7/unittest/case.py"}, {"linenr": 53, "function": "test_proxy_records_messages_sent_to_tv", "line": "tv.power()", "filename": "/Users/ops/Projects/PyKata/test/test_proxy_object_project.py"}]}, "result": "error", "name": "test_proxy_records_messages_sent_to_tv"}, {"error": {"message": "AttributeError: 'Proxy' object has no attribute 'power'", "traceback": [{"linenr": 329, "function": "run", "line": "testMethod()", "filename": "/usr/local/Cellar/python/2.7.12/Frameworks/Python.framework/Versions/2.7/lib/python2.7/unittest/case.py"}, {"linenr": 72, "function": "test_proxy_reports_methods_have_been_called", "line": "tv.power()", "filename": "/Users/ops/Projects/PyKata/test/test_proxy_object_project.py"}]}, "result": "error", "name": "test_proxy_reports_methods_have_been_called"}, {"error": {"message": "AttributeError: 'Proxy' object has no attribute 'power'", "traceback": [{"linenr": 329, "function": "run", "line": "testMethod()", "filename": "/usr/local/Cellar/python/2.7.12/Frameworks/Python.framework/Versions/2.7/lib/python2.7/unittest/case.py"}, {"linenr": 45, "function": "test_tv_methods_still_perform_their_function", "line": "tv.power()", "filename": "/Users/ops/Projects/PyKata/test/test_proxy_object_project.py"}]}, "result": "error", "name": "test_tv_methods_still_perform_their_function"}], "nr_error": 5, "nr_success": 2, "name": "test.test_proxy_object_project.AboutProxyObjectProject", "nr_failed": 0}, {"testcases": [{"result": "success", "name": "test_can_set_the_channel"}, {"result": "success", "name": "test_edge_case_on_off"}, {"result": "success", "name": "test_it_also_turns_off"}, {"result": "success", "name": "test_it_turns_on"}], "nr_error": 0, "nr_success": 4, "name": "test.test_proxy_object_project.TelevisionTest", "nr_failed": 0}, {"testcases": [{"error": {"message": "AssertionError: Lists differ: ['sam'] != ['sam.xls']\n\nFirst differing element 0:\n'sam'\n'sam.xls'\n\n- ['sam']\n+ ['sam.xls']\n?      ++++", "traceback": [{"linenr": 329, "function": "run", "line": "testMethod()", "filename": "/usr/local/Cellar/python/2.7.12/Frameworks/Python.framework/Versions/2.7/lib/python2.7/unittest/case.py"}, {"linenr": 140, "function": "test_anything_but_matching", "line": "['sam.xls'])", "filename": "/Users/ops/Projects/PyKata/test/test_regex.py"}, {"linenr": 513, "function": "assertEqual", "line": "assertion_func(first, second, msg=msg)", "filename": "/usr/local/Cellar/python/2.7.12/Frameworks/Python.framework/Versions/2.7/lib/python2.7/unittest/case.py"}, {"linenr": 742, "function": "assertListEqual", "line": "self.assertSequenceEqual(list1, list2, msg, seq_type=list)", "filename": "/usr/local/Cellar/python/2.7.12/Frameworks/Python.framework/Versions/2.7/lib/python2.7/unittest/case.py"}, {"linenr": 724, "function": "assertSequenceEqual", "line": "self.fail(msg)", "filename": "/usr/local/Cellar/python/2.7.12/Frameworks/Python.framework/Versions/2.7/lib/python2.7/unittest/case.py"}, {"linenr": 410, "function": "fail", "line": "raise self.failureException(msg)", "filename": "/usr/local/Cellar/python/2.7.12/Frameworks/Python.framework/Versions/2.7/lib/python2.7/unittest/case.py"}]}, "result": "failed", "name": "test_anything_but_matching"}, {"error": {"message": "AssertionError: 0 != 3", "traceback": [{"linenr": 329, "function": "run", "line": "testMethod()", "filename": "/usr/local/Cellar/python/2.7.12/Frameworks/Python.framework/Versions/2.7/lib/python2.7/unittest/case.py"}, {"linenr": 87, "function": "test_matching_any_character", "line": "3)", "filename": "/Users/ops/Projects/PyKata/test/test_regex.py"}, {"linenr": 513, "function": "assertEqual", "line": "assertion_func(first, second, msg=msg)", "filename": "/usr/local/Cellar/python/2.7.12/Frameworks/Python.framework/Versions/2.7/lib/python2.7/unittest/case.py"}, {"linenr": 506, "function": "_baseAssertEqual", "line": "raise self.failureException(msg)", "filename": "/usr/local/Cellar/python/2.7.12/Frameworks/Python.framework/Versions/2.7/lib/python2.7/unittest/case.py"}]}, "result": "failed", "name": "test_matching_any_character"}, {"error": {"message": "NameError: global name '__' is not defined", "traceback": [{"linenr": 329, "function": "run", "line": "testMethod()", "filename": "/usr/local/Cellar/python/2.7.12/Frameworks/Python.framework/Versions/2.7/lib/python2.7/unittest/case.py"}, {"linenr": 23, "function": "test_matching_literal_text", "line": "m = re.search(__, string)", "filename": "/Users/ops/Projects/PyKata/test/test_regex.py"}]}, "result": "error", "name": "test_matching_literal_text"}, {"error": {"message": "NameError: global name '__' is not defined", "traceback": [{"linenr": 329, "function": "run", "line": "testMethod()", "filename": "/usr/local/Cellar/python/2.7.12/Frameworks/Python.framework/Versions/2.7/lib/python2.7/unittest/case.py"}, {"linenr": 52, "function": "test_matching_literal_text_how_many", "line": "self.assertEqual(m, __)", "filename": "/Users/ops/Projects/PyKata/test/test_regex.py"}]}, "result": "error", "name": "test_matching_literal_text_how_many"}, {"error": {"message": "NameError: global name '__' is not defined", "traceback": [{"linenr": 329, "function": "run", "line": "testMethod()", "filename": "/usr/local/Cellar/python/2.7.12/Frameworks/Python.framework/Versions/2.7/lib/python2.7/unittest/case.py"}, {"linenr": 66, "function": "test_matching_literal_text_not_case_sensitivity", "line": "self.assertEqual(re.findall(\"felix\", string), __)", "filename": "/Users/ops/Projects/PyKata/test/test_regex.py"}]}, "result": "error", "name": "test_matching_literal_text_not_case_sensitivity"}, {"error": {"message": "AssertionError: 1 != 3", "traceback": [{"linenr": 329, "function": "run", "line": "testMethod()", "filename": "/usr/local/Cellar/python/2.7.12/Frameworks/Python.framework/Versions/2.7/lib/python2.7/unittest/case.py"}, {"linenr": 113, "function": "test_matching_set_character", "line": "3)", "filename": "/Users/ops/Projects/PyKata/test/test_regex.py"}, {"linenr": 513, "function": "assertEqual", "line": "assertion_func(first, second, msg=msg)", "filename": "/usr/local/Cellar/python/2.7.12/Frameworks/Python.framework/Versions/2.7/lib/python2.7/unittest/case.py"}, {"linenr": 506, "function": "_baseAssertEqual", "line": "raise self.failureException(msg)", "filename": "/usr/local/Cellar/python/2.7.12/Frameworks/Python.framework/Versions/2.7/lib/python2.7/unittest/case.py"}]}, "result": "failed", "name": "test_matching_set_character"}], "nr_error": 3, "nr_success": 0, "name": "test.test_regex.AboutRegex", "nr_failed": 3}, {"testcases": [{"error": {"message": "NameError: global name '____' is not defined", "traceback": [{"linenr": 329, "function": "run", "line": "testMethod()", "filename": "/usr/local/Cellar/python/2.7.12/Frameworks/Python.framework/Versions/2.7/lib/python2.7/unittest/case.py"}, {"linenr": 42, "function": "test_bare_bones_class_names_do_not_assume_the_current_scope", "line": "self.assertEqual(____, AboutScope.str == str)", "filename": "/Users/ops/Projects/PyKata/test/test_scope.py"}]}, "result": "error", "name": "test_bare_bones_class_names_do_not_assume_the_current_scope"}, {"error": {"message": "NameError: global name '_____' is not defined", "traceback": [{"linenr": 329, "function": "run", "line": "testMethod()", "filename": "/usr/local/Cellar/python/2.7.12/Frameworks/Python.framework/Versions/2.7/lib/python2.7/unittest/case.py"}, {"linenr": 61, "function": "test_constants_are_assumed_by_convention_only", "line": "self.assertEqual(_____, self.PI)", "filename": "/Users/ops/Projects/PyKata/test/test_scope.py"}]}, "result": "error", "name": "test_constants_are_assumed_by_convention_only"}, {"error": {"message": "NameError: global name '_____' is not defined", "traceback": [{"linenr": 329, "function": "run", "line": "testMethod()", "filename": "/usr/local/Cellar/python/2.7.12/Frameworks/Python.framework/Versions/2.7/lib/python2.7/unittest/case.py"}, {"linenr": 55, "function": "test_constants_are_defined_with_an_initial_uppercase_letter", "line": "self.assertAlmostEqual(_____, self.PI)", "filename": "/Users/ops/Projects/PyKata/test/test_scope.py"}]}, "result": "error", "name": "test_constants_are_defined_with_an_initial_uppercase_letter"}, {"error": {"message": "AttributeError: 'AboutScope' object has no attribute 'assertMatch'", "traceback": [{"linenr": 329, "function": "run", "line": "testMethod()", "filename": "/usr/local/Cellar/python/2.7.12/Frameworks/Python.framework/Versions/2.7/lib/python2.7/unittest/case.py"}, {"linenr": 23, "function": "test_dog_is_not_available_in_the_current_scope", "line": "self.assertMatch(__, ex[0])", "filename": "/Users/ops/Projects/PyKata/test/test_scope.py"}]}, "result": "error", "name": "test_dog_is_not_available_in_the_current_scope"}, {"error": {"message": "NameError: global name '__' is not defined", "traceback": [{"linenr": 329, "function": "run", "line": "testMethod()", "filename": "/usr/local/Cellar/python/2.7.12/Frameworks/Python.framework/Versions/2.7/lib/python2.7/unittest/case.py"}, {"linenr": 92, "function": "test_global_attributes_can_be_created_in_the_middle_of_a_class", "line": "self.assertEqual(__, deadly_bingo[5])", "filename": "/Users/ops/Projects/PyKata/test/test_scope.py"}]}, "result": "error", "name": "test_global_attributes_can_be_created_in_the_middle_of_a_class"}, {"error": {"message": "NameError: global name '____' is not defined", "traceback": [{"linenr": 329, "function": "run", "line": "testMethod()", "filename": "/usr/local/Cellar/python/2.7.12/Frameworks/Python.framework/Versions/2.7/lib/python2.7/unittest/case.py"}, {"linenr": 84, "function": "test_incrementing_with_global_counter", "line": "self.assertEqual(____, counter == start + 1)", "filename": "/Users/ops/Projects/PyKata/test/test_scope.py"}]}, "result": "error", "name": "test_incrementing_with_global_counter"}, {"error": {"message": "NameError: global name '____' is not defined", "traceback": [{"linenr": 329, "function": "run", "line": "testMethod()", "filename": "/usr/local/Cellar/python/2.7.12/Frameworks/Python.framework/Versions/2.7/lib/python2.7/unittest/case.py"}, {"linenr": 78, "function": "test_incrementing_with_local_counter", "line": "self.assertEqual(____, counter == start + 1)", "filename": "/Users/ops/Projects/PyKata/test/test_scope.py"}]}, "result": "error", "name": "test_incrementing_with_local_counter"}, {"error": {"message": "NameError: global name '____' is not defined", "traceback": [{"linenr": 329, "function": "run", "line": "testMethod()", "filename": "/usr/local/Cellar/python/2.7.12/Frameworks/Python.framework/Versions/2.7/lib/python2.7/unittest/case.py"}, {"linenr": 45, "function": "test_nested_string_is_not_the_same_as_the_system_string", "line": "self.assertEqual(____, self.str == type(\"HI\"))", "filename": "/Users/ops/Projects/PyKata/test/test_scope.py"}]}, "result": "error", "name": "test_nested_string_is_not_the_same_as_the_system_string"}, {"error": {"message": "NameError: global name '____' is not defined", "traceback": [{"linenr": 329, "function": "run", "line": "testMethod()", "filename": "/usr/local/Cellar/python/2.7.12/Frameworks/Python.framework/Versions/2.7/lib/python2.7/unittest/case.py"}, {"linenr": 48, "function": "test_str_without_self_prefix_stays_in_the_global_scope", "line": "self.assertEqual(____, str == type(\"HI\"))", "filename": "/Users/ops/Projects/PyKata/test/test_scope.py"}]}, "result": "error", "name": "test_str_without_self_prefix_stays_in_the_global_scope"}, {"error": {"message": "NameError: global name '__' is not defined", "traceback": [{"linenr": 329, "function": "run", "line": "testMethod()", "filename": "/usr/local/Cellar/python/2.7.12/Frameworks/Python.framework/Versions/2.7/lib/python2.7/unittest/case.py"}, {"linenr": 30, "function": "test_you_can_reference_nested_classes_using_the_scope_operator", "line": "self.assertEqual(__, fido.identify())", "filename": "/Users/ops/Projects/PyKata/test/test_scope.py"}]}, "result": "error", "name": "test_you_can_reference_nested_classes_using_the_scope_operator"}], "nr_error": 10, "nr_success": 0, "name": "test.test_scope.AboutScope", "nr_failed": 0}, {"testcases": [{"error": {"message": "AssertionError: 300 != None", "traceback": [{"linenr": 329, "function": "run", "line": "testMethod()", "filename": "/usr/local/Cellar/python/2.7.12/Frameworks/Python.framework/Versions/2.7/lib/python2.7/unittest/case.py"}, {"linenr": 73, "function": "test_ones_not_left_out", "line": "self.assertEqual(300, score([1, 2, 2, 2]))", "filename": "/Users/ops/Projects/PyKata/test/test_scoring_project.py"}, {"linenr": 513, "function": "assertEqual", "line": "assertion_func(first, second, msg=msg)", "filename": "/usr/local/Cellar/python/2.7.12/Frameworks/Python.framework/Versions/2.7/lib/python2.7/unittest/case.py"}, {"linenr": 506, "function": "_baseAssertEqual", "line": "raise self.failureException(msg)", "filename": "/usr/local/Cellar/python/2.7.12/Frameworks/Python.framework/Versions/2.7/lib/python2.7/unittest/case.py"}]}, "result": "failed", "name": "test_ones_not_left_out"}, {"error": {"message": "AssertionError: 100 != None", "traceback": [{"linenr": 329, "function": "run", "line": "testMethod()", "filename": "/usr/local/Cellar/python/2.7.12/Frameworks/Python.framework/Versions/2.7/lib/python2.7/unittest/case.py"}, {"linenr": 49, "function": "test_score_of_a_single_roll_of_1_is_100", "line": "self.assertEqual(100, score([1]))", "filename": "/Users/ops/Projects/PyKata/test/test_scoring_project.py"}, {"linenr": 513, "function": "assertEqual", "line": "assertion_func(first, second, msg=msg)", "filename": "/usr/local/Cellar/python/2.7.12/Frameworks/Python.framework/Versions/2.7/lib/python2.7/unittest/case.py"}, {"linenr": 506, "function": "_baseAssertEqual", "line": "raise self.failureException(msg)", "filename": "/usr/local/Cellar/python/2.7.12/Frameworks/Python.framework/Versions/2.7/lib/python2.7/unittest/case.py"}]}, "result": "failed", "name": "test_score_of_a_single_roll_of_1_is_100"}, {"error": {"message": "AssertionError: 50 != None", "traceback": [{"linenr": 329, "function": "run", "line": "testMethod()", "filename": "/usr/local/Cellar/python/2.7.12/Frameworks/Python.framework/Versions/2.7/lib/python2.7/unittest/case.py"}, {"linenr": 46, "function": "test_score_of_a_single_roll_of_5_is_50", "line": "self.assertEqual(50, score([5]))", "filename": "/Users/ops/Projects/PyKata/test/test_scoring_project.py"}, {"linenr": 513, "function": "assertEqual", "line": "assertion_func(first, second, msg=msg)", "filename": "/usr/local/Cellar/python/2.7.12/Frameworks/Python.framework/Versions/2.7/lib/python2.7/unittest/case.py"}, {"linenr": 506, "function": "_baseAssertEqual", "line": "raise self.failureException(msg)", "filename": "/usr/local/Cellar/python/2.7.12/Frameworks/Python.framework/Versions/2.7/lib/python2.7/unittest/case.py"}]}, "result": "failed", "name": "test_score_of_a_single_roll_of_5_is_50"}, {"error": {"message": "AssertionError: 1000 != None", "traceback": [{"linenr": 329, "function": "run", "line": "testMethod()", "filename": "/usr/local/Cellar/python/2.7.12/Frameworks/Python.framework/Versions/2.7/lib/python2.7/unittest/case.py"}, {"linenr": 58, "function": "test_score_of_a_triple_1_is_1000", "line": "self.assertEqual(1000, score([1, 1, 1]))", "filename": "/Users/ops/Projects/PyKata/test/test_scoring_project.py"}, {"linenr": 513, "function": "assertEqual", "line": "assertion_func(first, second, msg=msg)", "filename": "/usr/local/Cellar/python/2.7.12/Frameworks/Python.framework/Versions/2.7/lib/python2.7/unittest/case.py"}, {"linenr": 506, "function": "_baseAssertEqual", "line": "raise self.failureException(msg)", "filename": "/usr/local/Cellar/python/2.7.12/Frameworks/Python.framework/Versions/2.7/lib/python2.7/unittest/case.py"}]}, "result": "failed", "name": "test_score_of_a_triple_1_is_1000"}, {"error": {"message": "AssertionError: 0 != None", "traceback": [{"linenr": 329, "function": "run", "line": "testMethod()", "filename": "/usr/local/Cellar/python/2.7.12/Frameworks/Python.framework/Versions/2.7/lib/python2.7/unittest/case.py"}, {"linenr": 43, "function": "test_score_of_an_empty_list_is_zero", "line": "self.assertEqual(0, score([]))", "filename": "/Users/ops/Projects/PyKata/test/test_scoring_project.py"}, {"linenr": 513, "function": "assertEqual", "line": "assertion_func(first, second, msg=msg)", "filename": "/usr/local/Cellar/python/2.7.12/Frameworks/Python.framework/Versions/2.7/lib/python2.7/unittest/case.py"}, {"linenr": 506, "function": "_baseAssertEqual", "line": "raise self.failureException(msg)", "filename": "/usr/local/Cellar/python/2.7.12/Frameworks/Python.framework/Versions/2.7/lib/python2.7/unittest/case.py"}]}, "result": "failed", "name": "test_score_of_an_empty_list_is_zero"}, {"error": {"message": "AssertionError: 250 != None", "traceback": [{"linenr": 329, "function": "run", "line": "testMethod()", "filename": "/usr/local/Cellar/python/2.7.12/Frameworks/Python.framework/Versions/2.7/lib/python2.7/unittest/case.py"}, {"linenr": 68, "function": "test_score_of_mixed_is_sum", "line": "self.assertEqual(250, score([2, 5, 2, 2, 3]))", "filename": "/Users/ops/Projects/PyKata/test/test_scoring_project.py"}, {"linenr": 513, "function": "assertEqual", "line": "assertion_func(first, second, msg=msg)", "filename": "/usr/local/Cellar/python/2.7.12/Frameworks/Python.framework/Versions/2.7/lib/python2.7/unittest/case.py"}, {"linenr": 506, "function": "_baseAssertEqual", "line": "raise self.failureException(msg)", "filename": "/usr/local/Cellar/python/2.7.12/Frameworks/Python.framework/Versions/2.7/lib/python2.7/unittest/case.py"}]}, "result": "failed", "name": "test_score_of_mixed_is_sum"}, {"error": {"message": "AssertionError: 300 != None", "traceback": [{"linenr": 329, "function": "run", "line": "testMethod()", "filename": "/usr/local/Cellar/python/2.7.12/Frameworks/Python.framework/Versions/2.7/lib/python2.7/unittest/case.py"}, {"linenr": 52, "function": "test_score_of_multiple_1s_and_5s_is_the_sum_of_individual_scores", "line": "self.assertEqual(300, score([1, 5, 5, 1]))", "filename": "/Users/ops/Projects/PyKata/test/test_scoring_project.py"}, {"linenr": 513, "function": "assertEqual", "line": "assertion_func(first, second, msg=msg)", "filename": "/usr/local/Cellar/python/2.7.12/Frameworks/Python.framework/Versions/2.7/lib/python2.7/unittest/case.py"}, {"linenr": 506, "function": "_baseAssertEqual", "line": "raise self.failureException(msg)", "filename": "/usr/local/Cellar/python/2.7.12/Frameworks/Python.framework/Versions/2.7/lib/python2.7/unittest/case.py"}]}, "result": "failed", "name": "test_score_of_multiple_1s_and_5s_is_the_sum_of_individual_scores"}, {"error": {"message": "AssertionError: 200 != None", "traceback": [{"linenr": 329, "function": "run", "line": "testMethod()", "filename": "/usr/local/Cellar/python/2.7.12/Frameworks/Python.framework/Versions/2.7/lib/python2.7/unittest/case.py"}, {"linenr": 61, "function": "test_score_of_other_triples_is_100x", "line": "self.assertEqual(200, score([2, 2, 2]))", "filename": "/Users/ops/Projects/PyKata/test/test_scoring_project.py"}, {"linenr": 513, "function": "assertEqual", "line": "assertion_func(first, second, msg=msg)", "filename": "/usr/local/Cellar/python/2.7.12/Frameworks/Python.framework/Versions/2.7/lib/python2.7/unittest/case.py"}, {"linenr": 506, "function": "_baseAssertEqual", "line": "raise self.failureException(msg)", "filename": "/usr/local/Cellar/python/2.7.12/Frameworks/Python.framework/Versions/2.7/lib/python2.7/unittest/case.py"}]}, "result": "failed", "name": "test_score_of_other_triples_is_100x"}, {"error": {"message": "AssertionError: 0 != None", "traceback": [{"linenr": 329, "function": "run", "line": "testMethod()", "filename": "/usr/local/Cellar/python/2.7.12/Frameworks/Python.framework/Versions/2.7/lib/python2.7/unittest/case.py"}, {"linenr": 55, "function": "test_score_of_single_2s_3s_4s_and_6s_are_zero", "line": "self.assertEqual(0, score([2, 3, 4, 6]))", "filename": "/Users/ops/Projects/PyKata/test/test_scoring_project.py"}, {"linenr": 513, "function": "assertEqual", "line": "assertion_func(first, second, msg=msg)", "filename": "/usr/local/Cellar/python/2.7.12/Frameworks/Python.framework/Versions/2.7/lib/python2.7/unittest/case.py"}, {"linenr": 506, "function": "_baseAssertEqual", "line": "raise self.failureException(msg)", "filename": "/usr/local/Cellar/python/2.7.12/Frameworks/Python.framework/Versions/2.7/lib/python2.7/unittest/case.py"}]}, "result": "failed", "name": "test_score_of_single_2s_3s_4s_and_6s_are_zero"}], "nr_error": 0, "nr_success": 0, "name": "test.test_scoring_project.AboutScoringProject", "nr_failed": 9}, {"testcases": [{"error": {"message": "NameError: global name '__' is not defined", "traceback": [{"linenr": 329, "function": "run", "line": "testMethod()", "filename": "/usr/local/Cellar/python/2.7.12/Frameworks/Python.framework/Versions/2.7/lib/python2.7/unittest/case.py"}, {"linenr": 20, "function": "test_convert_the_set_into_a_list_to_sort_it", "line": "self.assertEqual(__, sorted(set('13245')))", "filename": "/Users/ops/Projects/PyKata/test/test_sets.py"}]}, "result": "error", "name": "test_convert_the_set_into_a_list_to_sort_it"}, {"error": {"message": "NameError: global name '__' is not defined", "traceback": [{"linenr": 329, "function": "run", "line": "testMethod()", "filename": "/usr/local/Cellar/python/2.7.12/Frameworks/Python.framework/Versions/2.7/lib/python2.7/unittest/case.py"}, {"linenr": 28, "function": "test_set_have_arithmetic_operators", "line": "self.assertEqual(__, scotsmen - warriors)", "filename": "/Users/ops/Projects/PyKata/test/test_sets.py"}]}, "result": "error", "name": "test_set_have_arithmetic_operators"}, {"error": {"message": "NameError: global name '__' is not defined", "traceback": [{"linenr": 329, "function": "run", "line": "testMethod()", "filename": "/usr/local/Cellar/python/2.7.12/Frameworks/Python.framework/Versions/2.7/lib/python2.7/unittest/case.py"}, {"linenr": 17, "function": "test_sets_are_unordered", "line": "self.assertEqual(set([__, __, __, __, __]), set('12345'))", "filename": "/Users/ops/Projects/PyKata/test/test_sets.py"}]}, "result": "error", "name": "test_sets_are_unordered"}, {"error": {"message": "NameError: global name '__' is not defined", "traceback": [{"linenr": 329, "function": "run", "line": "testMethod()", "filename": "/usr/local/Cellar/python/2.7.12/Frameworks/Python.framework/Versions/2.7/lib/python2.7/unittest/case.py"}, {"linenr": 14, "function": "test_sets_make_keep_lists_unique", "line": "self.assertEqual(__, there_can_only_be_only_one)", "filename": "/Users/ops/Projects/PyKata/test/test_sets.py"}]}, "result": "error", "name": "test_sets_make_keep_lists_unique"}, {"error": {"message": "NameError: global name '__' is not defined", "traceback": [{"linenr": 329, "function": "run", "line": "testMethod()", "filename": "/usr/local/Cellar/python/2.7.12/Frameworks/Python.framework/Versions/2.7/lib/python2.7/unittest/case.py"}, {"linenr": 40, "function": "test_we_can_compare_subsets", "line": "self.assertEqual(__, set('cake') <= set('cherry cake'))", "filename": "/Users/ops/Projects/PyKata/test/test_sets.py"}]}, "result": "error", "name": "test_we_can_compare_subsets"}, {"error": {"message": "NameError: global name '__' is not defined", "traceback": [{"linenr": 329, "function": "run", "line": "testMethod()", "filename": "/usr/local/Cellar/python/2.7.12/Frameworks/Python.framework/Versions/2.7/lib/python2.7/unittest/case.py"}, {"linenr": 36, "function": "test_we_can_query_set_membership", "line": "self.assertEqual(__, 127 in set([127, 0, 0, 1]))", "filename": "/Users/ops/Projects/PyKata/test/test_sets.py"}]}, "result": "error", "name": "test_we_can_query_set_membership"}], "nr_error": 6, "nr_success": 0, "name": "test.test_sets.AboutSets", "nr_failed": 0}, {"testcases": [{"error": {"message": "NameError: global name '__' is not defined", "traceback": [{"linenr": 329, "function": "run", "line": "testMethod()", "filename": "/usr/local/Cellar/python/2.7.12/Frameworks/Python.framework/Versions/2.7/lib/python2.7/unittest/case.py"}, {"linenr": 27, "function": "test_any_python_expression_may_be_interpolated", "line": "self.assertEqual(__, string)", "filename": "/Users/ops/Projects/PyKata/test/test_string_manipulation.py"}]}, "result": "error", "name": "test_any_python_expression_may_be_interpolated"}, {"error": {"message": "NameError: global name '__' is not defined", "traceback": [{"linenr": 329, "function": "run", "line": "testMethod()", "filename": "/usr/local/Cellar/python/2.7.12/Frameworks/Python.framework/Versions/2.7/lib/python2.7/unittest/case.py"}, {"linenr": 19, "function": "test_formatted_values_can_be_shown_in_any_order_or_be_repeated", "line": "self.assertEqual(__, string)", "filename": "/Users/ops/Projects/PyKata/test/test_string_manipulation.py"}]}, "result": "error", "name": "test_formatted_values_can_be_shown_in_any_order_or_be_repeated"}, {"error": {"message": "NameError: global name '__' is not defined", "traceback": [{"linenr": 329, "function": "run", "line": "testMethod()", "filename": "/usr/local/Cellar/python/2.7.12/Frameworks/Python.framework/Versions/2.7/lib/python2.7/unittest/case.py"}, {"linenr": 62, "function": "test_raw_strings_do_not_interpret_escape_characters", "line": "self.assertEqual(__, string)", "filename": "/Users/ops/Projects/PyKata/test/test_string_manipulation.py"}]}, "result": "error", "name": "test_raw_strings_do_not_interpret_escape_characters"}, {"error": {"message": "NameError: global name '__' is not defined", "traceback": [{"linenr": 329, "function": "run", "line": "testMethod()", "filename": "/usr/local/Cellar/python/2.7.12/Frameworks/Python.framework/Versions/2.7/lib/python2.7/unittest/case.py"}, {"linenr": 38, "function": "test_single_characters_can_be_represented_by_integers", "line": "self.assertEqual(__, ord('a'))", "filename": "/Users/ops/Projects/PyKata/test/test_string_manipulation.py"}]}, "result": "error", "name": "test_single_characters_can_be_represented_by_integers"}, {"error": {"message": "NameError: global name '__' is not defined", "traceback": [{"linenr": 329, "function": "run", "line": "testMethod()", "filename": "/usr/local/Cellar/python/2.7.12/Frameworks/Python.framework/Versions/2.7/lib/python2.7/unittest/case.py"}, {"linenr": 69, "function": "test_strings_can_be_joined", "line": "self.assertEqual(__, ' '.join(words))", "filename": "/Users/ops/Projects/PyKata/test/test_string_manipulation.py"}]}, "result": "error", "name": "test_strings_can_be_joined"}, {"error": {"message": "NameError: global name '__' is not defined", "traceback": [{"linenr": 329, "function": "run", "line": "testMethod()", "filename": "/usr/local/Cellar/python/2.7.12/Frameworks/Python.framework/Versions/2.7/lib/python2.7/unittest/case.py"}, {"linenr": 44, "function": "test_strings_can_be_split", "line": "self.assertEqual([__, __, __], words)", "filename": "/Users/ops/Projects/PyKata/test/test_string_manipulation.py"}]}, "result": "error", "name": "test_strings_can_be_split"}, {"error": {"message": "NameError: global name '__' is not defined", "traceback": [{"linenr": 329, "function": "run", "line": "testMethod()", "filename": "/usr/local/Cellar/python/2.7.12/Frameworks/Python.framework/Versions/2.7/lib/python2.7/unittest/case.py"}, {"linenr": 54, "function": "test_strings_can_be_split_with_different_patterns", "line": "self.assertEqual([__, __, __, __], words)", "filename": "/Users/ops/Projects/PyKata/test/test_string_manipulation.py"}]}, "result": "error", "name": "test_strings_can_be_split_with_different_patterns"}, {"error": {"message": "NameError: global name '__' is not defined", "traceback": [{"linenr": 329, "function": "run", "line": "testMethod()", "filename": "/usr/local/Cellar/python/2.7.12/Frameworks/Python.framework/Versions/2.7/lib/python2.7/unittest/case.py"}, {"linenr": 72, "function": "test_strings_can_change_case", "line": "self.assertEqual(__, 'guido'.capitalize())", "filename": "/Users/ops/Projects/PyKata/test/test_string_manipulation.py"}]}, "result": "error", "name": "test_strings_can_change_case"}, {"error": {"message": "NameError: global name '__' is not defined", "traceback": [{"linenr": 329, "function": "run", "line": "testMethod()", "filename": "/usr/local/Cellar/python/2.7.12/Frameworks/Python.framework/Versions/2.7/lib/python2.7/unittest/case.py"}, {"linenr": 13, "function": "test_use_format_to_interpolate_variables", "line": "self.assertEqual(__, string)", "filename": "/Users/ops/Projects/PyKata/test/test_string_manipulation.py"}]}, "result": "error", "name": "test_use_format_to_interpolate_variables"}, {"error": {"message": "NameError: global name '__' is not defined", "traceback": [{"linenr": 329, "function": "run", "line": "testMethod()", "filename": "/usr/local/Cellar/python/2.7.12/Frameworks/Python.framework/Versions/2.7/lib/python2.7/unittest/case.py"}, {"linenr": 35, "function": "test_you_can_get_a_single_character_from_a_string", "line": "self.assertEqual(__, string[1])", "filename": "/Users/ops/Projects/PyKata/test/test_string_manipulation.py"}]}, "result": "error", "name": "test_you_can_get_a_single_character_from_a_string"}, {"error": {"message": "NameError: global name '__' is not defined", "traceback": [{"linenr": 329, "function": "run", "line": "testMethod()", "filename": "/usr/local/Cellar/python/2.7.12/Frameworks/Python.framework/Versions/2.7/lib/python2.7/unittest/case.py"}, {"linenr": 31, "function": "test_you_can_get_a_substring_from_a_string", "line": "self.assertEqual(__, string[7:10])", "filename": "/Users/ops/Projects/PyKata/test/test_string_manipulation.py"}]}, "result": "error", "name": "test_you_can_get_a_substring_from_a_string"}], "nr_error": 11, "nr_success": 0, "name": "test.test_string_manipulation.AboutStringManipulation", "nr_failed": 0}, {"testcases": [{"result": "success", "name": "test_adjacent_strings_are_concatenated_automatically"}, {"result": "success", "name": "test_double_quoted_strings_are_strings"}, {"result": "success", "name": "test_escaping_quotes_at_the_end_of_triple_quoted_string"}, {"result": "success", "name": "test_most_strings_interpret_escape_characters"}, {"result": "success", "name": "test_plus_concatenates_strings"}, {"result": "success", "name": "test_plus_equals_also_leaves_original_string_unmodified"}, {"result": "success", "name": "test_plus_equals_will_append_to_end_of_string"}, {"result": "success", "name": "test_plus_will_not_modify_original_strings"}, {"result": "success", "name": "test_raw_strings_are_also_strings"}, {"result": "success", "name": "test_single_quoted_strings_are_also_strings"}, {"result": "success", "name": "test_triple_quote_strings_are_also_strings"}, {"result": "success", "name": "test_triple_quoted_strings_can_span_lines"}, {"result": "success", "name": "test_triple_quoted_strings_need_less_escaping"}, {"result": "success", "name": "test_triple_single_quotes_work_too"}, {"result": "success", "name": "test_use_backslash_at_the_end_of_a_line_to_continue_onto_the_next_line"}, {"result": "success", "name": "test_use_backslash_for_escaping_quotes_in_strings"}, {"result": "success", "name": "test_use_double_quotes_to_create_strings_with_single_quotes"}, {"result": "success", "name": "test_use_single_quotes_to_create_string_with_double_quotes"}], "nr_error": 0, "nr_success": 18, "name": "test.test_strings.AboutStrings", "nr_failed": 0}, {"testcases": [{"error": {"message": "AssertionError: 'equilateral' != None", "traceback": [{"linenr": 329, "function": "run", "line": "testMethod()", "filename": "/usr/local/Cellar/python/2.7.12/Frameworks/Python.framework/Versions/2.7/lib/python2.7/unittest/case.py"}, {"linenr": 12, "function": "test_equilateral_triangles_have_equal_sides", "line": "self.assertEqual('equilateral', triangle(2, 2, 2))", "filename": "/Users/ops/Projects/PyKata/test/test_triangle_project.py"}, {"linenr": 513, "function": "assertEqual", "line": "assertion_func(first, second, msg=msg)", "filename": "/usr/local/Cellar/python/2.7.12/Frameworks/Python.framework/Versions/2.7/lib/python2.7/unittest/case.py"}, {"linenr": 506, "function": "_baseAssertEqual", "line": "raise self.failureException(msg)", "filename": "/usr/local/Cellar/python/2.7.12/Frameworks/Python.framework/Versions/2.7/lib/python2.7/unittest/case.py"}]}, "result": "failed", "name": "test_equilateral_triangles_have_equal_sides"}, {"error": {"message": "AssertionError: 'isosceles' != None", "traceback": [{"linenr": 329, "function": "run", "line": "testMethod()", "filename": "/usr/local/Cellar/python/2.7.12/Frameworks/Python.framework/Versions/2.7/lib/python2.7/unittest/case.py"}, {"linenr": 16, "function": "test_isosceles_triangles_have_exactly_two_sides_equal", "line": "self.assertEqual('isosceles', triangle(3, 4, 4))", "filename": "/Users/ops/Projects/PyKata/test/test_triangle_project.py"}, {"linenr": 513, "function": "assertEqual", "line": "assertion_func(first, second, msg=msg)", "filename": "/usr/local/Cellar/python/2.7.12/Frameworks/Python.framework/Versions/2.7/lib/python2.7/unittest/case.py"}, {"linenr": 506, "function": "_baseAssertEqual", "line": "raise self.failureException(msg)", "filename": "/usr/local/Cellar/python/2.7.12/Frameworks/Python.framework/Versions/2.7/lib/python2.7/unittest/case.py"}]}, "result": "failed", "name": "test_isosceles_triangles_have_exactly_two_sides_equal"}, {"error": {"message": "AssertionError: 'scalene' != None", "traceback": [{"linenr": 329, "function": "run", "line": "testMethod()", "filename": "/usr/local/Cellar/python/2.7.12/Frameworks/Python.framework/Versions/2.7/lib/python2.7/unittest/case.py"}, {"linenr": 22, "function": "test_scalene_triangles_have_no_equal_sides", "line": "self.assertEqual('scalene', triangle(3, 4, 5))", "filename": "/Users/ops/Projects/PyKata/test/test_triangle_project.py"}, {"linenr": 513, "function": "assertEqual", "line": "assertion_func(first, second, msg=msg)", "filename": "/usr/local/Cellar/python/2.7.12/Frameworks/Python.framework/Versions/2.7/lib/python2.7/unittest/case.py"}, {"linenr": 506, "function": "_baseAssertEqual", "line": "raise self.failureException(msg)", "filename": "/usr/local/Cellar/python/2.7.12/Frameworks/Python.framework/Versions/2.7/lib/python2.7/unittest/case.py"}]}, "result": "failed", "name": "test_scalene_triangles_have_no_equal_sides"}], "nr_error": 0, "nr_success": 0, "name": "test.test_triangle_project.AboutTriangleProject", "nr_failed": 3}, {"testcases": [{"error": {"message": "AssertionError: TriangleError not raised", "traceback": [{"linenr": 329, "function": "run", "line": "testMethod()", "filename": "/usr/local/Cellar/python/2.7.12/Frameworks/Python.framework/Versions/2.7/lib/python2.7/unittest/case.py"}, {"linenr": 15, "function": "test_illegal_triangles_throw_exceptions", "line": "self.assertRaises(TriangleError, triangle, 0, 0, 0)", "filename": "/Users/ops/Projects/PyKata/test/test_triangle_project2.py"}, {"linenr": 473, "function": "assertRaises", "line": "callableObj(*args, **kwargs)", "filename": "/usr/local/Cellar/python/2.7.12/Frameworks/Python.framework/Versions/2.7/lib/python2.7/unittest/case.py"}, {"linenr": 116, "function": "__exit__", "line": "\"{0} not raised\".format(exc_name))", "filename": "/usr/local/Cellar/python/2.7.12/Frameworks/Python.framework/Versions/2.7/lib/python2.7/unittest/case.py"}]}, "result": "failed", "name": "test_illegal_triangles_throw_exceptions"}], "nr_error": 0, "nr_success": 0, "name": "test.test_triangle_project2.AboutTriangleProject2", "nr_failed": 1}, {"testcases": [{"result": "success", "name": "test_blank_strings_are_treated_as_false"}, {"result": "success", "name": "test_empty_collections_are_treated_as_false"}, {"result": "success", "name": "test_everything_else_is_treated_as_true"}, {"result": "success", "name": "test_false_is_treated_as_false"}, {"result": "success", "name": "test_none_is_treated_as_false"}, {"result": "success", "name": "test_true_is_treated_as_true"}, {"result": "success", "name": "test_zero_is_treated_as_false"}], "nr_error": 0, "nr_success": 7, "name": "test.test_true_and_false.AboutTrueAndFalse", "nr_failed": 0}, {"testcases": [{"result": "success", "name": "test_creating_a_tuple"}, {"result": "success", "name": "test_creating_empty_tuples"}, {"result": "success", "name": "test_tuple_constructor_can_be_surprising"}, {"result": "success", "name": "test_tuples_are_good_for_representing_records"}, {"result": "success", "name": "test_tuples_are_immutable_so_appending_is_not_possible"}, {"result": "success", "name": "test_tuples_are_immutable_so_item_assignment_is_not_possible"}, {"result": "success", "name": "test_tuples_can_be_embedded"}, {"result": "success", "name": "test_tuples_can_only_be_changed_through_replacement"}, {"result": "success", "name": "test_tuples_of_one_look_peculiar"}], "nr_error": 0, "nr_success": 9, "name": "test.test_tuples.AboutTuples", "nr_failed": 0}, {"testcases": [{"error": {"message": "NameError: global name '__' is not defined", "traceback": [{"linenr": 329, "function": "run", "line": "testMethod()", "filename": "/usr/local/Cellar/python/2.7.12/Frameworks/Python.framework/Versions/2.7/lib/python2.7/unittest/case.py"}, {"linenr": 26, "function": "test_counting_lines", "line": "self.assertEqual(__, self.count_lines(\"example_file.txt\"))", "filename": "/Users/ops/Projects/PyKata/test/test_with_statements.py"}]}, "result": "error", "name": "test_counting_lines"}, {"error": {"message": "NameError: global name '__' is not defined", "traceback": [{"linenr": 329, "function": "run", "line": "testMethod()", "filename": "/usr/local/Cellar/python/2.7.12/Frameworks/Python.framework/Versions/2.7/lib/python2.7/unittest/case.py"}, {"linenr": 89, "function": "test_counting_lines2", "line": "self.assertEqual(__, self.count_lines2(\"example_file.txt\"))", "filename": "/Users/ops/Projects/PyKata/test/test_with_statements.py"}]}, "result": "error", "name": "test_counting_lines2"}, {"error": {"message": "NameError: global name '__' is not defined", "traceback": [{"linenr": 329, "function": "run", "line": "testMethod()", "filename": "/usr/local/Cellar/python/2.7.12/Frameworks/Python.framework/Versions/2.7/lib/python2.7/unittest/case.py"}, {"linenr": 45, "function": "test_finding_lines", "line": "self.assertEqual(__, self.find_line(\"example_file.txt\"))", "filename": "/Users/ops/Projects/PyKata/test/test_with_statements.py"}]}, "result": "error", "name": "test_finding_lines"}, {"error": {"message": "NameError: global name '__' is not defined", "traceback": [{"linenr": 329, "function": "run", "line": "testMethod()", "filename": "/usr/local/Cellar/python/2.7.12/Frameworks/Python.framework/Versions/2.7/lib/python2.7/unittest/case.py"}, {"linenr": 98, "function": "test_finding_lines2", "line": "self.assertEqual(__, self.find_line2(\"example_file.txt\"))", "filename": "/Users/ops/Projects/PyKata/test/test_with_statements.py"}]}, "result": "error", "name": "test_finding_lines2"}, {"error": {"message": "NameError: global name '__' is not defined", "traceback": [{"linenr": 329, "function": "run", "line": "testMethod()", "filename": "/usr/local/Cellar/python/2.7.12/Frameworks/Python.framework/Versions/2.7/lib/python2.7/unittest/case.py"}, {"linenr": 108, "function": "test_open_already_has_its_own_built_in_context_manager", "line": "self.assertEqual(__, self.count_lines3(\"example_file.txt\"))", "filename": "/Users/ops/Projects/PyKata/test/test_with_statements.py"}]}, "result": "error", "name": "test_open_already_has_its_own_built_in_context_manager"}], "nr_error": 5, "nr_success": 0, "name": "test.test_with_statements.AboutWithStatements", "nr_failed": 0}], "metadata": {"command": "/Users/ops/.virtualenvs/pykata/bin/nosetests --with-json-extended", "cwd": "/Users/ops/Projects/PyKata", "time": 1476026944.021351}}